<?xml version="1.0" encoding="utf-8"?>
<!-- This URDF was automatically created by SolidWorks to URDF Exporter! Originally created by Stephen Brawner (brawner@gmail.com) 
 Commit Version: 1.6.0-4-g7f85cfe  Build Version: 1.6.7995.38578
 For more information, please see http://wiki.ros.org/sw_urdf_exporter -->
<robot
  name="KARM_EM_v2">
<link name="world"/>
  <link
    name="base_link">
    <inertial>
      <origin
        xyz="-0.00103581 0.0 0.04093116"
        rpy="0 0 0" />
      <mass
        value="0.50587804" />
      <inertia
        ixx="0.00132199"
        ixy="0.0"
        ixz="0.00000760"
        iyy="0.00135029"
        iyz="0.0"
        izz="0.00189639" />
    </inertial>
    <visual>
      <origin
        xyz="0 0 0"
        rpy="0 0 0" />
      <geometry>
        <mesh
          filename="meshes/ASM_EM_V2_LINK_0.STL" />
      </geometry>
      <material
        name="">
        <color
          rgba="0.75294 0.75294 0.75294 1" />
      </material>
    </visual>
    <collision>
      <origin
        xyz="0 0 0"
        rpy="0 0 0" />
      <geometry>
        <mesh
          filename="meshes/ASM_EM_V2_LINK_0.STL" />
      </geometry>
    </collision>
  </link>
  <link
    name="link1">
    <inertial>
      <origin
        xyz="-0.00012971 -0.03627547 0.07258973"
        rpy="0 0 0" />
      <mass
        value="6.73005605" />
      <inertia
        ixx="0.05762149"
        ixy="-0.00006714"
        ixz="-0.00001782"
        iyy="0.03664038"
        iyz="-0.01209112"
        izz="0.03415321" />
    </inertial>
    <visual>
      <origin
        xyz="0 0 0"
        rpy="0 0 0" />
      <geometry>
        <mesh
          filename="meshes/ASM_EM_V2_LINK_1.STL" />
      </geometry>
      <material
        name="">
        <color
          rgba="0.75294 0.75294 0.75294 1" />
      </material>
    </visual>
    <collision>
      <origin
        xyz="0 0 0"
        rpy="0 0 0" />
      <geometry>
        <mesh
          filename="meshes/ASM_EM_V2_LINK_1.STL" />
      </geometry>
    </collision>
  </link>

  <link
    name="link2">
    <inertial>
      <origin
        xyz="0 -0.07828883 0.02158454"
        rpy="0 0 0" />
      <mass
        value="1.03696228" />
      <inertia
        ixx="0.00585872"
        ixy="-0.00000001"
        ixz="0.0"
        iyy="0.00499784"
        iyz="-0.00021746"
        izz="0.00585872" />
    </inertial>
    <visual>
      <origin
        xyz="0 0 0"
        rpy="0 0 0" />
      <geometry>
        <mesh
          filename="meshes/ASM_EM_V2_LINK_2.STL" />
      </geometry>
      <material
        name="">
        <color
          rgba="0.752941176470588 0.752941176470588 0.752941176470588 1" />
      </material>
    </visual>
    <collision>
      <origin
        xyz="0 0 0"
        rpy="0 0 0" />
      <geometry>
        <mesh
          filename="meshes/ASM_EM_V2_LINK_2.STL" />
      </geometry>
    </collision>
  </link>

  <link
    name="link3">
    <inertial>
      <origin
        xyz="-0.00007377 0.03129504 0.34046856"
        rpy="0 0 0" />
      <mass
        value="8.53351346" />
      <inertia
        ixx="0.67442861"
        ixy="0.00002201"
        ixz="-0.00021578"
        iyy="0.65414252"
        iyz="0.06857224"
        izz="0.03701854" />
    </inertial>
    <visual>
      <origin
        xyz="0 0 0"
        rpy="0 0 0" />
      <geometry>
        <mesh
          filename="meshes/ASM_EM_V2_LINK_3.STL" />
      </geometry>
      <material
        name="">
        <color
          rgba="0.75294 0.75294 0.75294 1" />
      </material>
    </visual>
    <collision>
      <origin
        xyz="0 0 0"
        rpy="0 0 0" />
      <geometry>
        <mesh
          filename="meshes/ASM_EM_V2_LINK_3.STL" />
      </geometry>
    </collision>
  </link>

  <link
    name="link4">
    <inertial>
      <origin
        xyz="0.0 0.07828883 0.02158454"
        rpy="0 0 0" />
      <mass
        value="1.03696228" />
      <inertia
        ixx="0.00585872"
        ixy="0.0"
        ixz="0.0"
        iyy="0.00499784"
        iyz="0.00021746"
        izz="0.00479989" />
    </inertial>
    <visual>
      <origin
        xyz="0 0 0"
        rpy="0 0 0" />
      <geometry>
        <mesh
          filename="meshes/ASM_EM_V2_LINK_4.STL" />
      </geometry>
      <material
        name="">
        <color
          rgba="0.752941176470588 0.752941176470588 0.752941176470588 1" />
      </material>
    </visual>
    <collision>
      <origin
        xyz="0 0 0"
        rpy="0 0 0" />
      <geometry>
        <mesh
          filename="meshes/ASM_EM_V2_LINK_4.STL" />
      </geometry>
    </collision>
  </link>

  <link
    name="link5">
    <inertial>
      <origin
        xyz="-0.00007975 0.03383054 0.23087355"
        rpy="0 0 0" />
      <mass
        value="7.89416673" />
      <inertia
        ixx="0.30885258"
        ixy="0.00002377"
        ixz="-0.00015419"
        iyy="0.28924225"
        iyz="0.04446799"
        izz="0.03516201" />
    </inertial>
    <visual>
      <origin
        xyz="0 0 0"
        rpy="0 0 0" />
      <geometry>
        <mesh
          filename="meshes/ASM_EM_V2_LINK_5.STL" />
      </geometry>
      <material
        name="">
        <color
          rgba="0.75294 0.75294 0.75294 1" />
      </material>
    </visual>
    <collision>
      <origin
        xyz="0 0 0"
        rpy="0 0 0" />
      <geometry>
        <mesh
          filename="meshes/ASM_EM_V2_LINK_5.STL" />
      </geometry>
    </collision>
  </link>

  <link
    name="link6">
    <inertial>
      <origin
        xyz="0.00020364 0.09335466 0.07814514"
        rpy="0 0 0" />
      <mass
        value="4.17204018" />
      <inertia
        ixx="0.02564449"
        ixy="0.00003403"
        ixz="-0.00004296"
        iyy="0.02310433"
        iyz="-0.00116219"
        izz="0.01188389" />
    </inertial>
    <visual>
      <origin
        xyz="0 0 0"
        rpy="0 0 0" />
      <geometry>
        <mesh
          filename="meshes/ASM_EM_V2_LINK_6.STL" />
      </geometry>
      <material
        name="">
        <color
          rgba="0.752941176470588 0.752941176470588 0.752941176470588 1" />
      </material>
    </visual>
    <collision>
      <origin
        xyz="0 0 0"
        rpy="0 0 0" />
      <geometry>
        <mesh
          filename="meshes/ASM_EM_V2_LINK_6.STL" />
      </geometry>
    </collision>
  </link>

  <link
    name="link7">
    <inertial>
      <origin
        xyz="0.00001055 -0.00228688 0.11844420"
        rpy="0 0 0" />
      <mass
        value="1.54531322" />
      <inertia
        ixx="0.00332840"
        ixy="-0.00002715"
        ixz="-0.00000961"
        iyy="0.00369572"
        iyz="-0.00004800"
        izz="0.00245411" />
    </inertial>
    <visual>
      <origin
        xyz="0 0 0"
        rpy="0 0 0" />
      <geometry>
        <mesh
          filename="meshes/ASM_EM_V2_LINK_7.STL" />
      </geometry>
      <material
        name="">
        <color
          rgba="0.752941176470588 0.752941176470588 0.752941176470588 1" />
      </material>
    </visual>
    <collision>
      <origin
        xyz="0 0 0"
        rpy="0 0 0" />
      <geometry>
        <mesh
          filename="meshes/ASM_EM_V2_LINK_7.STL" />
      </geometry>
    </collision>
  </link>

  <link name="tcp">
      <inertial>
        <origin xyz="0 0 0"  rpy="0 0 0" />
        <mass value="0.0"/>
        <inertia  ixx="0.0"      ixy="0"      ixz="0"      iyy="0.0"      iyz="0"      izz="0.0" />
     </inertial>
  </link>


  <joint name="world_fixed" type="fixed">
    <parent link="world"/>
    <child link="base_link"/>
    <origin xyz="0 0 0" rpy="0 0 0"/>
    <axis xyz="0 0 1"/>
  </joint>

  <joint
    name="joint1"
    type="revolute">
    <origin
      xyz="0 0 0.078"
      rpy="0 0 0" />
    <parent
      link="base_link" />
    <child
      link="link1" />
    <axis
      xyz="0 0 1" />
    <limit
      lower="-3.14"
      upper="3.14"
      effort="400"
      velocity="3.14" />
  </joint>

  <joint
    name="joint2"
    type="revolute">
    <origin
      xyz="0 -0.104 0.121"
      rpy="0 0 0" />
    <parent
      link="link1" />
    <child
      link="link2" />
    <axis
      xyz="0 1 0" />
    <limit
      lower="-3.14"
      upper="3.14"
      effort="400"
      velocity="3.14" />
  </joint>

  <joint
    name="joint3"
    type="revolute">
    <origin
      xyz="0.0 -0.088 0.105"
      rpy="0 0 0" />
    <parent
      link="link2" />
    <child
      link="link3" />
    <axis
      xyz="0 0 1" />
    <limit
      lower="-3.14"
      upper="3.14"
      effort="400"
      velocity="3.14" />
  </joint>

  <joint
    name="joint4"
    type="revolute">
    <origin
      xyz="0.0 0.104 0.597"
      rpy="0 0 0" />
    <parent
      link="link3" />
    <child
      link="link4" />
    <axis
      xyz="0 1 0" />
    <limit
      lower="-3.14"
      upper="3.14"
      effort="400"
      velocity="3.14" />
  </joint>

  <joint
    name="joint5"
    type="revolute">
    <origin
      xyz="0.0 0.088 0.105"
      rpy="0 0 0" />
    <parent
      link="link4" />
    <child
      link="link5" />
    <axis
      xyz="0 0 1" />
    <limit
      lower="-3.14"
      upper="3.14"
      effort="400"
      velocity="3.14" />
  </joint>

  <joint
    name="joint6"
    type="revolute">
    <origin
      xyz="0 0.104 0.397"
      rpy="0 0 0" />
    <parent
      link="link5" />
    <child
      link="link6" />
    <axis
      xyz="0 1 0" />
    <limit
      lower="-3.14"
      upper="3.14"
      effort="400"
      velocity="3.14" />
  </joint>

  <joint
    name="joint7"
    type="revolute">
    <origin
      xyz="0.0 0.088 0.121"
      rpy="0 0 0" />
    <parent
      link="link6" />
    <child
      link="link7" />
    <axis
      xyz="0 0 1" />
    <limit
      lower="-3.14"
      upper="3.14"
      effort="400"
      velocity="3.14" />
  </joint>

  <joint name="tcp_fixed" type="fixed">
    <parent link="link7"/>
    <child link="tcp"/>
    <origin xyz="0 0 0.173222" rpy="0 0 0"/>
  </joint>
</robot>
