<?xml version="1.0" ?>
<!-- =================================================================================== -->
<!-- |    This document was autogenerated by xacro from space_arm.xacro                    | -->
<!-- |    EDITING THIS FILE BY HAND IS NOT RECOMMENDED                                 | -->
<!-- =================================================================================== -->
<robot name="space_arm">
  <material name="black">
    <color rgba="0.0 0.0 0.0 1.0"/>
  </material>
  <material name="blue">
    <color rgba="0.0 0.0 0.8 1.0"/>
  </material>
  <material name="green">
    <color rgba="0.0 0.8 0.0 1.0"/>
  </material>
  <material name="grey_">
    <color rgba="0.2 0.2 0.2 1.0"/>
  </material>
  <material name="orange">
    <color rgba="1.0 0.4235294117647059 0.0392156862745098 1.0"/>
  </material>
  <material name="brown">
    <color rgba="0.8705882352941177 0.8117647058823529 0.7647058823529411 1.0"/>
  </material>
  <material name="red">
    <color rgba="0.8 0.0 0.0 1.0"/>
  </material>
  <material name="white">
    <color rgba="1.0 1.0 1.0 1.0"/>
  </material>
  <material name="metal">
    <color rgba="0.768627450980392 0.749019607843137 0.729411764705882 1"/>
  </material>
  <material name="metal_grey">
    <color rgba="0.501960784313725 0.501960784313725 0.501960784313725 1"/>
  </material>
  <material name="metal_white">
    <color rgba="0.866666666666667 0.866666666666667 0.890196078431373 1"/>
  </material>
  
  <!-- <material name="grey"> <color rgba="0.5 0.5 0.5 1"/> </material> -->

  <!-- world-->
    <link name="world"/>

  <!-- VirtualLink p1-->
    <link name="VirtualLink_p1">
      <inertial>
          <mass value="0.0000001" />
          <origin xyz="0.0 0.0 0.0" rpy="0 0 0" />
          <inertia ixx="0.0000001" ixy="0" ixz="0" iyy="0.0000001" iyz="0" izz="0.0000001" />
      </inertial>
      <collision>
        <geometry>
          <box size="0.00 0.00 0.00"/>
        </geometry>
        <origin rpy="0 0 0" xyz="0 0 0"/>
      </collision>
    </link>

  <!-- VirtualLink p2-->
  <link name="VirtualLink_p2">
    <inertial>
          <mass value="0.0000001" />
          <origin xyz="0.0 0.0 0.0" rpy="0 0 0" />
          <inertia ixx="0.0000001" ixy="0" ixz="0" iyy="0.0000001" iyz="0" izz="0.0000001" />
      </inertial>

    <collision>
      <geometry>
        <box size="0.00 0.00 0.00"/>
      </geometry>
      <origin rpy="0 0 0" xyz="0 0 0"/>
    </collision>
  </link>

  <!-- VirtualLink p3-->
  <link name="VirtualLink_p3">
    <inertial>
          <mass value="0.0000001" />
          <origin xyz="0.0 0.0 0.0" rpy="0 0 0" />
          <inertia ixx="0.0000001" ixy="0" ixz="0" iyy="0.0000001" iyz="0" izz="0.0000001" />
      </inertial>
    <collision>
      <geometry>
        <box size="0.00 0.00 0.00"/>
      </geometry>
      <origin rpy="0 0 0" xyz="0 0 0"/>
    </collision>
  </link>

  <!-- VirtualLink r1-->
  <link name="VirtualLink_r1">
    <inertial>
          <mass value="0.0000001" />
          <origin xyz="0.0 0.0 0.0" rpy="0 0 0" />
          <inertia ixx="0.0000001" ixy="0" ixz="0" iyy="0.0000001" iyz="0" izz="0.0000001" />
      </inertial>
    <collision>
      <geometry>
        <box size="0.00 0.00 0.00"/>
      </geometry>
      <origin rpy="0 0 0" xyz="0 0 0"/>
    </collision>
  </link>

  <!-- VirtualLink r2-->
  <link name="VirtualLink_r2">
    <inertial>
          <mass value="0.0000001" />
          <origin xyz="0.0 0.0 0.0" rpy="0 0 0" />
          <inertia ixx="0.0000001" ixy="0" ixz="0" iyy="0.0000001" iyz="0" izz="0.0000001" />
      </inertial>
    <collision>
      <geometry>
        <box size="0.00 0.00 0.00"/>
      </geometry>
      <origin rpy="0 0 0" xyz="0 0 0"/>
    </collision>
  </link>

  <link name="link0">
    <visual>
      <origin rpy="0 0 0" xyz="0 0 0"/>
      <geometry>
        <mesh filename="meshes/stl/Link_0.STL"/>
      </geometry>
      <material name="metal_grey"/>
    </visual>

    <inertial>
      <mass value="14.299"/>
      <origin rpy="0 0 0" xyz="0.0 -0.01869 0.75176"/>
      <inertia ixx="4.7569" ixy="3.5447e-06" ixz="1.3257e-05" iyy="4.7075" iyz="0.21788" izz="0.16593"/>
    </inertial>
  </link>
  <link name="link1">
    <visual>
      <origin rpy="0 0 0" xyz="0 0 0"/>
      <geometry>
        <mesh filename="meshes/stl/Link_1.STL"/>
      </geometry>
      <material name="metal_grey"/>
    </visual>

    <inertial>
      <mass value="0.63842732"/>
      <origin rpy="0 0 0" xyz="0.00311394 -0.04860885 0.00031774"/>
      <inertia ixx="0.00038493" ixy="-1.048e-05" ixz="-1.02e-06" iyy="0.00041146" iyz="4.9e-06" izz="0.00051529"/>
    </inertial>
  </link>
  <link name="link2">
    <visual>
      <origin rpy="0 0 0" xyz="0 0 0"/>
      <geometry>
        <mesh filename="meshes/stl/Link_2.STL"/>
      </geometry>
      <material name="metal_grey"/>
    </visual>

    <inertial>
      <mass value="0.60158865"/>
      <origin rpy="0 0 0" xyz="0.00089160 -0.00240254 -0.08332539"/>
      <inertia ixx="0.00182502" ixy="5.27e-06" ixz="5.22e-05" iyy="0.00195006" iyz="-5.189e-05" izz="0.00047439"/>
    </inertial>
  </link>
  <link name="link3">
    <visual>
      <origin rpy="0 0 0" xyz="0 0 0"/>
      <geometry>
        <mesh filename="meshes/stl/Link_3.STL"/>
      </geometry>
      <material name="metal_grey"/>
    </visual>

    <inertial>
      <mass value="0.74955005"/>
      <origin rpy="0 0 0" xyz="-0.00248083 0.00215363 -0.10416744"/>
      <inertia ixx="0.00250752" ixy="-6.41e-06" ixz="-5.774e-05" iyy="0.00245844" iyz="7.894e-05" izz="0.00039769"/>
    </inertial>
  </link>
  <link name="link4">
    <visual>
      <origin rpy="0 0 0" xyz="0 0 0"/>
      <geometry>
        <mesh filename="meshes/stl/Link_4.STL"/>
      </geometry>
      <material name="metal_grey"/>
    </visual>

    <inertial>
      <mass value="0.57916453"/>
      <origin rpy="0 0 0" xyz="-0.00215405 -0.00036606 -0.08370247"/>
      <inertia ixx="0.00168738" ixy="-2.17e-06" ixz="-4.517e-05" iyy="0.00161999" iyz="-1.849e-05" izz="0.00040018"/>
    </inertial>
  </link>
  <link name="link5">
    <visual>
      <origin rpy="0 0 0" xyz="0 0 0"/>
      <geometry>
        <mesh filename="meshes/stl/Link_5.STL"/>
      </geometry>
      <material name="metal_grey"/>
    </visual>

    <inertial>
      <mass value="0.74955005"/>
      <origin rpy="0 0 0" xyz="-0.00248083 -0.00215363 -0.10416744"/>
      <inertia ixx="0.00250752" ixy="-6.41e-06" ixz="-5.774e-05" iyy="0.00245844" iyz="7.894e-05" izz="0.00039769"/>
    </inertial>
  </link>
  <link name="link6">
    <visual>
      <origin rpy="0 0 0" xyz="0 0 0"/>
      <geometry>
        <mesh filename="meshes/stl/Link_6.STL"/>
      </geometry>
      <material name="metal_grey"/>
    </visual>

    <inertial>
      <mass value="0.59063954"/>
      <origin rpy="0 0 0" xyz="0.00099609 0.00016953 -0.05061212"/>
      <inertia ixx="0.00030422" ixy="7.6e-07" ixz="-2.85e-06" iyy="0.00042387" iyz="-1.32e-06" izz="0.0003724"/>
    </inertial>
  </link>
  <link name="link7">
    <visual>
      <origin rpy="0 0 0" xyz="0 0 0"/>
      <geometry>
        <mesh filename="meshes/stl/Link_7.STL"/>
      </geometry>
      <material name="metal_grey"/>
    </visual>

    <inertial>
      <mass value="0.59063954"/>
      <origin rpy="0 0 0" xyz="0.00221466 0.00090916 -0.00853216"/>
      <inertia ixx="0.00030422" ixy="7.6e-07" ixz="-2.85e-06" iyy="0.00042387" iyz="-1.32e-06" izz="0.0003724"/>
    </inertial>
  </link>
  <link name="tcp">
    <inertial>
      <mass value="0.000001" />
      <origin xyz="0.0 0.0 0.0" rpy="0 0 0" />
      <inertia ixx="0.000001" ixy="0" ixz="0" iyy="0.000001" iyz="0" izz="0.000001" />
    </inertial>
  </link>

  <!-- VirtualJoint_p1 -->
  <joint name="VirtualJoint_px" type="prismatic">
    <origin xyz="0 0 0" rpy="0 0 0" />
    <parent link="world" />
    <child link="VirtualLink_p1" />
    <axis xyz="1 0 0" />
    <limit
      lower="-1000"
      upper="1000"
      effort="100"
      velocity="1000" />
  </joint>

  <!-- VirtualJoint_p2 -->
  <joint name="VirtualJoint_py" type="prismatic">
    <origin xyz="0 0 0" rpy="0 0 0" />
    <parent link="VirtualLink_p1" />
    <child link="VirtualLink_p2" />
    <axis xyz="0 1 0" />
    <limit
      lower="-1000"
      upper="1000"
      effort="100"
      velocity="1000" />
  </joint>

<!-- VirtualJoint_p3 -->
  <joint name="VirtualJoint_pz" type="prismatic">
    <origin xyz="0 0 0" rpy="0 0 0" />
    <parent link="VirtualLink_p2" />
    <child link="VirtualLink_p3" />
    <axis xyz="0 0 1" />
    <limit
      lower="-1000"
      upper="1000"
      effort="100"
      velocity="1000" />
  </joint>

  <!-- VirtualJoint_r1 -->
  <joint name="VirtualJoint_rx" type="revolute">
    <origin xyz="0 0 0" rpy="0 0 0" />
    <parent link="VirtualLink_p3" />
    <child link="VirtualLink_r1" />
    <axis xyz="1 0 0" />
    <limit
      lower="-1000"
      upper="1000"
      effort="100"
      velocity="1000" />
  </joint>

  <!-- VirtualJoint_r2 -->
  <joint name="VirtualJoint_ry" type="revolute">
    <origin xyz="0 0 0" rpy="0 0 0" />
    <parent link="VirtualLink_r1" />
    <child link="VirtualLink_r2" />
    <axis xyz="0 1 0" />
    <limit
      lower="-1000"
      upper="1000"
      effort="100"
      velocity="1000" />
  </joint>

  <!-- VirtualJoint_r3 -->
  <joint name="VirtualJoint_rz" type="revolute">
    <origin xyz="0 0 0" rpy="0 0 0" />
    <parent link="VirtualLink_r2" />
    <child link="link0" />
    <axis xyz="0 0 1" />
    <limit
      lower="-1000"
      upper="1000"
      effort="100"
      velocity="1000" />
  </joint>

  <joint name="joint0" type="revolute">
    <parent link="link0"/>
    <child link="link1"/>
    <origin rpy="0 0 0" xyz="0 0 -0.2287"/>
    <axis xyz="0 0 1"/>
    <limit effort="10" lower="-3.0543261909900763" upper="3.0543261909900763" velocity="1"/>
  </joint>
  <joint name="joint1" type="revolute">
    <parent link="link1"/>
    <child link="link2"/>
    <origin rpy="0 0 0" xyz="0 0 -0.054"/>
    <axis xyz="1 0 0"/>
    <limit effort="10" lower="-3.0543261909900763" upper="3.0543261909900763" velocity="1"/>
  </joint>
  <joint name="joint2" type="revolute">
    <parent link="link2"/>
    <child link="link3"/>
    <origin rpy="0 0 0" xyz="0 0 -0.1458"/>
    <axis xyz="0 0 1"/>
    <limit effort="10" lower="-3.0543261909900763" upper="3.0543261909900763" velocity="1"/>
  </joint>
  <joint name="joint3" type="revolute">
    <parent link="link3"/>
    <child link="link4"/>
    <origin rpy="0 0 0" xyz="0 0 -0.1542"/>
    <axis xyz="1 0 0"/>
    <limit effort="10" lower="-3.0543261909900763" upper="3.0543261909900763" velocity="1"/>
  </joint>
  <joint name="joint4" type="revolute">
    <parent link="link4"/>
    <child link="link5"/>
    <origin rpy="0 0 0" xyz="0 0 -0.1458"/>
    <axis xyz="0 0 1"/>
    <limit effort="10" lower="-3.0543261909900763" upper="3.0543261909900763" velocity="1"/>
  </joint>
  <joint name="joint5" type="revolute">
    <parent link="link5"/>
    <child link="link6"/>
    <origin rpy="0 0 0" xyz="0 0 -0.1542"/>
    <axis xyz="1 0 0"/>
    <limit effort="10" lower="-3.752457891787808" upper="3.752457891787808" velocity="1"/>
  </joint>
  <joint name="joint6" type="revolute">
    <parent link="link6"/>
    <child link="link7"/>
    <origin rpy="0 0 0" xyz="0 0 -0.054"/>
    <axis xyz="0 0 1"/>
    <limit effort="10" lower="-3.752457891787808" upper="3.752457891787808" velocity="1"/>
  </joint>
  <joint name="tcp_fixed" type="fixed">
    <parent link="link7"/>
    <child link="tcp"/>
    <origin rpy="0 0 0" xyz="0 0 -0.2357"/>
  </joint>
</robot>

