<?xml version="1.0" encoding="utf-8"?>
<!-- This URDF was automatically created by SolidWorks to URDF Exporter! Originally created by Stephen Brawner (brawner@gmail.com) 
 Commit Version: 1.6.0-4-g7f85cfe  Build Version: 1.6.7995.38578
 For more information, please see http://wiki.ros.org/sw_urdf_exporter -->
<robot
  name="KARM_EQM">
<link name="world"/>
  <link
    name="base_link">
    <inertial>
      <origin
        xyz="8.2542E-05 -2.0757E-11 0.048979"
        rpy="0 0 0" />
      <mass
        value="2.7715" />
      <inertia
        ixx="0.0051534"
        ixy="9.8483E-12"
        ixz="2.6648E-05"
        iyy="0.005029"
        iyz="3.019E-12"
        izz="0.0072657" />
    </inertial>
    <visual>
      <origin
        xyz="0 0 0"
        rpy="0 0 0" />
      <geometry>
        <mesh
          filename="meshes/base_link.STL" />
      </geometry>
      <material
        name="">
        <color
          rgba="0.75294 0.75294 0.75294 1" />
      </material>
    </visual>
    <collision>
      <origin
        xyz="0 0 0"
        rpy="0 0 0" />
      <geometry>
        <mesh
          filename="meshes/base_link.STL" />
      </geometry>
    </collision>
  </link>
  <link
    name="link1">
    <inertial>
      <origin
        xyz="-0.0001351 0.0044415 0.089359"
        rpy="0 0 0" />
      <mass
        value="6.5395" />
      <inertia
        ixx="0.023852"
        ixy="1.1192E-07"
        ixz="1.5092E-07"
        iyy="0.022043"
        iyz="-0.00028982"
        izz="0.01995" />
    </inertial>
    <visual>
      <origin
        xyz="0 0 0"
        rpy="0 0 0" />
      <geometry>
        <mesh
          filename="meshes/link1.STL" />
      </geometry>
      <material
        name="">
        <color
          rgba="0.75294 0.75294 0.75294 1" />
      </material>
    </visual>
    <collision>
      <origin
        xyz="0 0 0"
        rpy="0 0 0" />
      <geometry>
        <mesh
          filename="meshes/link1.STL" />
      </geometry>
    </collision>
  </link>

  <link
    name="link2">
    <inertial>
      <origin
        xyz="0.447266049338714 9.81277627616803E-06 -0.0864465546497567"
        rpy="0 0 0" />
      <mass
        value="14.5254250159894" />
      <inertia
        ixx="0.0316449332553447"
        ixy="5.58291621087347E-07"
        ixz="0.000547486320569549"
        iyy="0.139457648132206"
        iyz="-1.36084653057748E-06"
        izz="0.139926786135881" />
    </inertial>
    <visual>
      <origin
        xyz="0 0 0"
        rpy="0 0 0" />
      <geometry>
        <mesh
          filename="meshes/link2.STL" />
      </geometry>
      <material
        name="">
        <color
          rgba="0.752941176470588 0.752941176470588 0.752941176470588 1" />
      </material>
    </visual>
    <collision>
      <origin
        xyz="0 0 0"
        rpy="0 0 0" />
      <geometry>
        <mesh
          filename="meshes/link2.STL" />
      </geometry>
    </collision>
  </link>

  <link
    name="link3">
    <inertial>
      <origin
        xyz="-0.00013626 -0.013622 0.099896"
        rpy="0 0 0" />
      <mass
        value="6.4825" />
      <inertia
        ixx="0.023483"
        ixy="5.8965E-07"
        ixz="-4.0613E-08"
        iyy="0.021463"
        iyz="0.00049908"
        izz="0.020008" />
    </inertial>
    <visual>
      <origin
        xyz="0 0 0"
        rpy="0 0 0" />
      <geometry>
        <mesh
          filename="meshes/link3.STL" />
      </geometry>
      <material
        name="">
        <color
          rgba="0.75294 0.75294 0.75294 1" />
      </material>
    </visual>
    <collision>
      <origin
        xyz="0 0 0"
        rpy="0 0 0" />
      <geometry>
        <mesh
          filename="meshes/link3.STL" />
      </geometry>
    </collision>
  </link>

  <link
    name="link4">
    <inertial>
      <origin
        xyz="0.0308962489888813 7.79267188454942E-08 -0.0753185892478983"
        rpy="0 0 0" />
      <mass
        value="5.77091277717193" />
      <inertia
        ixx="0.0153724702367589"
        ixy="8.77488405691915E-08"
        ixz="0.000896956837443678"
        iyy="0.0173511322184264"
        iyz="1.53191862133355E-07"
        izz="0.0174707209690322" />
    </inertial>
    <visual>
      <origin
        xyz="0 0 0"
        rpy="0 0 0" />
      <geometry>
        <mesh
          filename="meshes/link4.STL" />
      </geometry>
      <material
        name="">
        <color
          rgba="0.752941176470588 0.752941176470588 0.752941176470588 1" />
      </material>
    </visual>
    <collision>
      <origin
        xyz="0 0 0"
        rpy="0 0 0" />
      <geometry>
        <mesh
          filename="meshes/link4.STL" />
      </geometry>
    </collision>
  </link>

  <link
    name="link5">
    <inertial>
      <origin
        xyz="-7.294E-05 -0.007814 0.48332"
        rpy="0 0 0" />
      <mass
        value="13.5" />
      <inertia
        ixx="0.20727"
        ixy="1.3048E-06"
        ixz="4.1067E-07"
        iyy="0.20542"
        iyz="0.00015902"
        izz="0.03354" />
    </inertial>
    <visual>
      <origin
        xyz="0 0 0"
        rpy="0 0 0" />
      <geometry>
        <mesh
          filename="meshes/link5.STL" />
      </geometry>
      <material
        name="">
        <color
          rgba="0.75294 0.75294 0.75294 1" />
      </material>
    </visual>
    <collision>
      <origin
        xyz="0 0 0"
        rpy="0 0 0" />
      <geometry>
        <mesh
          filename="meshes/link5.STL" />
      </geometry>
    </collision>
  </link>

  <link
    name="link6">
    <inertial>
      <origin
        xyz="0.0226409262393772 -0.000135290448474516 0.0905585316249733"
        rpy="0 0 0" />
      <mass
        value="6.53953654625201" />
      <inertia
        ixx="0.0199500209234715"
        ixy="-1.50549505787494E-07"
        ixz="-0.000289821877154332"
        iyy="0.0238523137351639"
        iyz="-1.11733382781844E-07"
        izz="0.0220428528009073" />
    </inertial>
    <visual>
      <origin
        xyz="0 0 0"
        rpy="0 0 0" />
      <geometry>
        <mesh
          filename="meshes/link6.STL" />
      </geometry>
      <material
        name="">
        <color
          rgba="0.752941176470588 0.752941176470588 0.752941176470588 1" />
      </material>
    </visual>
    <collision>
      <origin
        xyz="0 0 0"
        rpy="0 0 0" />
      <geometry>
        <mesh
          filename="meshes/link6.STL" />
      </geometry>
    </collision>
  </link>

  <link
    name="link7">
    <inertial>
      <origin
        xyz="-2.00217781812251E-05 -1.80958026341216E-11 0.0387539433791355"
        rpy="0 0 0" />
      <mass
        value="2.91241532737351" />
      <inertia
        ixx="0.00516383226388649"
        ixy="2.68745926335947E-09"
        ixz="-2.24244031252904E-06"
        iyy="0.00516422825221854"
        iyz="-1.44105361312819E-12"
        izz="0.00707129033492822" />
    </inertial>
    <visual>
      <origin
        xyz="0 0 0"
        rpy="0 0 0" />
      <geometry>
        <mesh
          filename="meshes/link7.STL" />
      </geometry>
      <material
        name="">
        <color
          rgba="0.752941176470588 0.752941176470588 0.752941176470588 1" />
      </material>
    </visual>
    <collision>
      <origin
        xyz="0 0 0"
        rpy="0 0 0" />
      <geometry>
        <mesh
          filename="meshes/link7.STL" />
      </geometry>
    </collision>
  </link>

  <link name="tcp">
      <inertial>
        <origin xyz="0 0 0"  rpy="0 0 0" />
        <mass value="0.0"/>
        <inertia  ixx="0.0"      ixy="0"      ixz="0"      iyy="0.0"      iyz="0"      izz="0.0" />
     </inertial>
  </link>


  <joint name="world_fixed" type="fixed">
    <parent link="world"/>
    <child link="base_link"/>
    <origin xyz="0 0 0" rpy="0 0 0"/>
    <axis xyz="0 0 1"/>
  </joint>

  <joint
    name="joint1"
    type="revolute">
    <origin
      xyz="0 0 0.087"
      rpy="0 0 3.141592" />
    <parent
      link="base_link" />
    <child
      link="link1" />
    <axis
      xyz="0 0 1" />
    <limit
      lower="-3.14"
      upper="3.14"
      effort="400"
      velocity="3.14" />
  </joint>

  <joint
    name="joint2"
    type="revolute">
    <origin
      xyz="0 0.097 0.112"
      rpy="1.5708 -1.5708 0" />
    <parent
      link="link1" />
    <child
      link="link2" />
    <axis
      xyz="0 0 1" />
    <limit
      lower="-3.14"
      upper="3.14"
      effort="400"
      velocity="3.14" />
  </joint>

  <joint
    name="joint3"
    type="revolute">
    <origin
      xyz="0.988 0 -0.095"
      rpy="-1.5708 0 -1.5708" />
    <parent
      link="link2" />
    <child
      link="link3" />
    <axis
      xyz="0 0 1" />
    <limit
      lower="-3.14"
      upper="3.14"
      effort="400"
      velocity="3.14" />
  </joint>

  <joint
    name="joint4"
    type="revolute">
    <origin
      xyz="0 -0.097 0.112"
      rpy="-1.5708 -1.5708 0" />
    <parent
      link="link3" />
    <child
      link="link4" />
    <axis
      xyz="0 0 -1" />
    <limit
      lower="-3.14"
      upper="3.14"
      effort="400"
      velocity="3.14" />
  </joint>

  <joint
    name="joint5"
    type="revolute">
    <origin
      xyz="0.114 0 -0.095"
      rpy="1.5708 0 1.5708" />
    <parent
      link="link4" />
    <child
      link="link5" />
    <axis
      xyz="0 0 1" />
    <limit
      lower="-3.14"
      upper="3.14"
      effort="400"
      velocity="3.14" />
  </joint>

  <joint
    name="joint6"
    type="revolute">
    <origin
      xyz="0 -0.097 0.786"
      rpy="-1.5704 -1.5708 3.1412" />
    <parent
      link="link5" />
    <child
      link="link6" />
    <axis
      xyz="0 0 1" />
    <limit
      lower="-3.14"
      upper="3.14"
      effort="400"
      velocity="3.14" />
  </joint>

  <joint
    name="joint7"
    type="revolute">
    <origin
      xyz="0.114 0 0.095"
      rpy="-1.5708 0 -1.5708" />
    <parent
      link="link6" />
    <child
      link="link7" />
    <axis
      xyz="0 0 1" />
    <limit
      lower="-3.14"
      upper="3.14"
      effort="400"
      velocity="3.14" />
  </joint>

  <joint name="tcp_fixed" type="fixed">
    <parent link="link7"/>
    <child link="tcp"/>
    <origin xyz="0 0 0.083" rpy="0 0 0"/>
  </joint>
</robot>
