<?xml version="1.0" ?>
<!-- =================================================================================== -->
<!-- |    This document was autogenerated by xacro from indyrp2.xacro                  | -->
<!-- |    EDITING THIS FILE BY HAND IS NOT RECOMMENDED                                 | -->
<!-- =================================================================================== -->
<robot name="indy12_v2_sat">
  <material name="black">
    <color rgba="0.0 0.0 0.0 1.0"/>
  </material>
  <material name="blue">
    <color rgba="0.0 0.0 0.8 1.0"/>
  </material>
  <material name="green">
    <color rgba="0.0 0.8 0.0 1.0"/>
  </material>
  <material name="grey_">
    <color rgba="0.2 0.2 0.2 1.0"/>
  </material>
  <material name="orange">
    <color rgba="1.0 0.4235294117647059 0.0392156862745098 1.0"/>
  </material>
  <material name="brown">
    <color rgba="0.8705882352941177 0.8117647058823529 0.7647058823529411 1.0"/>
  </material>
  <material name="red">
    <color rgba="0.8 0.0 0.0 1.0"/>
  </material>
  <material name="white">
    <color rgba="1.0 1.0 1.0 1.0"/>
  </material>
  <material name="metal">
    <color rgba="0.768627450980392 0.749019607843137 0.729411764705882 1"/>
  </material>
  <material name="metal_grey">
    <color rgba="0.501960784313725 0.501960784313725 0.501960784313725 1"/>
  </material>
  <material name="metal_white">
    <color rgba="0.866666666666667 0.866666666666667 0.890196078431373 1"/>
  </material>

  <link name="world"/>
  <link name="link_px"/>
  <link name="link_py"/>
  <link name="link_pz"/>
  <link name="link_rz"/>
  <link name="link_ry"/>

   <joint name="Px" type="prismatic">
    <parent link="world"/>
    <child link="link_px"/>
    <origin rpy="0 0 0" xyz="+0.0 +0.0 0.0"/>
    <axis xyz="1 0 0"/>
    <limit effort="10000" lower="-20" upper="20" velocity="1000"/>
  </joint>
  <joint name="Py" type="prismatic">
    <parent link="link_px"/>
    <child link="link_py"/>
    <origin rpy="0 0 0" xyz="+0.0 +0.0 0.0"/>
    <axis xyz="0 1 0"/>
    <limit effort="10000" lower="-10" upper="10" velocity="1000"/>
  </joint>
  <joint name="Pz" type="prismatic">
    <parent link="link_py"/>
    <child link="link_pz"/>
    <origin rpy="0 0 0" xyz="+0.0 +0.0 0.0"/>
    <axis xyz="0 0 1"/>
    <limit effort="10000" lower="-2" upper="2" velocity="1000"/>
  </joint>
  <joint name="Rz" type="revolute">
    <parent link="link_pz"/>
    <child link="link_rz"/>
    <origin rpy="0 0 0" xyz="+0.0 +0.0 0.0"/>
    <axis xyz="0 0 1"/>
    <limit effort="10000" lower="-3.14" upper="3.14" velocity="1000"/>
  </joint>
  <joint name="Ry" type="revolute">
    <parent link="link_rz"/>
    <child link="link_ry"/>
    <origin rpy="0 0 0" xyz="+0.0 +0.0 0.0"/>
    <axis xyz="0 1 0"/>
    <limit effort="10000" lower="-3.14" upper="3.14" velocity="1000"/>
  </joint>
  <joint name="Rx" type="revolute">
    <parent link="link_ry"/>
    <child link="l_tcp"/>
    <origin rpy="0 0 0" xyz="+0.0 +0.0 0.0"/>
    <axis xyz="1 0 0"/>
    <limit effort="10000" lower="-3.14" upper="3.14" velocity="1000"/>
  </joint>

  <link name="l_tcp">
    <inertial>
      <mass value="0"/>
      <origin rpy="0 0 0" xyz="0.0 0.0 0.0"/>
      <inertia ixx="0.0" ixy="0.0" ixz="0.0" iyy="0.0" iyz="0.0" izz="0.0"/>
    </inertial>
  </link>

  <link name="FTSensor">
    <inertial>
      <mass value="0.000"/>
      <origin rpy="0 0 0" xyz="0.0 0.0 0.0"/>
      <inertia ixx="0.0" ixy="0.0" ixz="0.0" iyy="0.0" iyz="0.0" izz="0.0"/>
    </inertial>
  </link>

  <joint name="ft_sensor_joint" type="fixed">
    <parent link="l_tcp"/>
    <child link="FTSensor"/>
    <origin rpy="0.0 0  3.1415926536" xyz="0.0 0.0 0.1048"/>
  </joint> 

  <joint name="CRS_fixed" type="fixed">
    <parent link="FTSensor"/>
    <child link="l_CRS_black"/>
    <origin rpy="0.0 0  0" xyz="0.0 0.0 0.0"/>
  </joint> 

  <!-- CRS Base -->
  <link name="l_CRS_black">
    <visual>
       <geometry>
        <mesh filename="meshes/CRS_black.stl"/>
      </geometry>
      <origin rpy="0 0 0" xyz="0.00 0 0"/>
        <material name="black"/>
    </visual>
    <visual>
    <geometry>
        <mesh filename="meshes/CRS_grey.stl"/>
      </geometry>
      <origin rpy="0 0 0" xyz="0.00 0 0"/>
        <material name="white_grey"/>
    </visual>
    <inertial>
      <mass value="500.0"/>
      <origin rpy="0 0 0" xyz="0.0 0.0 0.0"/>
      <inertia ixx="195" ixy="0.0" ixz="0.0" iyy="195" iyz="0.0" izz="120"/>
    </inertial>
  </link>

  <joint name="sat_to_indy12_fixed" type="fixed">
    <parent link="FTSensor"/>
    <child link="link0"/>
    <origin rpy="0    0 -1.5708" xyz="-0.19232 0.20744 0.0345"/>
  </joint>

 <link name="link0">
    <visual>
      <origin rpy="0 0 0" xyz="0 0 0"/>
      <geometry>
        <mesh filename="meshes/indy12_v2/link0.stl"/>
      </geometry>
      <material name="metal_grey"/>
    </visual>

    <inertial>
      <origin rpy="0 0 0" xyz="0.00263938 -0.00000218 0.03583192"/>
      <mass value="2.56262283"/>
      <inertia ixx="0.01217749" ixy="0.00001183" ixz="-0.00010915" iyy="0.01291700" iyz="-0.00000185" izz="0.02096803"/>
    </inertial>
  </link>
  <link name="link1">
    <visual>
      <origin rpy="0 0 0" xyz="0 0 0"/>
      <geometry>
        <mesh filename="meshes/indy12_v2/link1.stl"/>
      </geometry>
      <material name="metal_grey"/>
    </visual>

    <inertial>
      <origin rpy="0 0 0" xyz="0.00008557 -0.04328154 0.18159328"/>
      <mass value="23.04941339"/>
      <inertia ixx="0.30202876" ixy="0.00007051" ixz="-0.00000638" iyy="0.25465324" iyz="-0.09152012" izz="0.10765691"/>
    </inertial>
  </link>
  <link name="link2">
    <visual>
      <origin rpy="0 0 0" xyz="0 0 0"/>
      <geometry>
        <mesh filename="meshes/indy12_v2/link2.stl"/>
      </geometry>
      <material name="metal_grey"/>
    </visual>

    <inertial>
      <origin rpy="0 0 0" xyz="0 -0.09582491 0.08847946"/>
      <mass value="8.96934807"/>
      <inertia ixx="+0.10217692" ixy="-0.00000038" ixz="0.00000041" iyy="+0.09870504" iyz="-0.01342194" izz="+0.03775572"/>
    </inertial>
  </link>
  <link name="link3">
    <visual>
      <origin rpy="0 0 0" xyz="0 0 0"/>
      <geometry>
        <mesh filename="meshes/indy12_v2/link3.stl"/>
      </geometry>
      <material name="metal_grey"/>
    </visual>

    <inertial>
      <origin rpy="0 0 0" xyz="0.00000177 0.01814888 0.21567452"/>
      <mass value="8.45645221"/>
      <inertia ixx="+0.14750527" ixy="+0.00000067" ixz="+0.00000173" iyy="+0.14140192" iyz="+0.01943665" izz="+0.03100903"/>
    </inertial>
  </link>
  <link name="link4">
    <visual>
      <origin rpy="0 0 0" xyz="0 0 0"/>
      <geometry>
        <mesh filename="meshes/indy12_v2/link4.stl"/>
      </geometry>
      <material name="metal_grey"/>
    </visual>

    <inertial>
      <origin rpy="0 0 0" xyz="-0.00000483 0.08958341 0.06692026"/>
      <mass value="5.10779343"/>
      <inertia ixx="+0.03950342" ixy="0.00000061" ixz="+0.00000051" iyy="+0.03644218" iyz="0.00639327" izz="0.01615892"/>
    </inertial>
  </link>
  <link name="link5">
    <visual>
      <origin rpy="0 0 3.141592" xyz="0 0 0"/>
      <geometry>
        <mesh filename="meshes/indy12_v2/link5.stl"/>
      </geometry>
      <material name="metal_grey"/>
    </visual>

    <inertial>
      <origin rpy="0 0 0" xyz="0.00015551 0.04669128 0.22088570"/>
      <mass value="5.05476208"/>
      <inertia ixx="0.10945505" ixy="-0.00008325" ixz="0.00008149" iyy="0.10032484" iyz="-0.02374104" izz="0.01927371"/>
    </inertial>
  </link>
  <link name="link6">
    <visual>
      <origin rpy="0 0 3.141592" xyz="0 0 0"/>
      <geometry>
        <mesh filename="meshes/indy12_v2/link6.stl"/>
      </geometry>
      <material name="metal_grey"/>
    </visual>

    <inertial>
      <origin rpy="0 0 0" xyz="-0.00014038 0.00014038 0.02034922"/>
      <mass value="3.54178915"/>
      <inertia ixx="0.00947309" ixy="0.00000368" ixz="-0.00000055" iyy="0.00901900" iyz="-0.00038601" izz="0.00603120"/>
    </inertial>
  </link>
  <link name="link7">
    <visual>
      <origin rpy="0 0 3.141592" xyz="0 0 0"/>
      <geometry>
        <mesh filename="meshes/indy12_v2/link7.stl"/>
      </geometry>
      <material name="metal_grey"/>
    </visual>

    <inertial>
      <origin rpy="0 0 0" xyz="0.0003115 0.0005641 0.0364598"/>
      <mass value="1.00684783"/>
      <inertia ixx="+0.00174119" ixy="0.00000018" ixz="+0.00000083" iyy="+0.00173263" iyz="-0.00000199" izz="+0.00223183"/>
    </inertial>
  </link>
  <link name="tool_plange">
      <origin rpy="0 0 0" xyz="-0.00191829, -0.00711865, 0.0632705"/>
 <inertial>
        <origin xyz="-0.00191829, -0.00711865, 0.0632705"  rpy="0 0 0" />        
        <mass value="2.6"/>
        <inertia  ixx="0.00716708"      ixy="0.000227877"      ixz="-0.000273462"      iyy="0.00704539"      iyz="0.000290156"      izz=" 0.00665249" />
     </inertial>
    <visual>
      <origin rpy="0 0 0" xyz="0 0 0"/>
      <geometry>
        <mesh filename="meshes/plange.stl"/>
      </geometry>
      <material name="metal_grey"/>
    </visual>

    <inertial>
      <origin rpy="0 0 0" xyz="0.0003115 -0.0005641 0.0364598"/>
      <mass value="0.300"/>
      <inertia ixx="+0.00174119" ixy="0.00000018" ixz="+0.00000083" iyy="+0.00173263" iyz="-0.00000199" izz="+0.00223183"/>
    </inertial>
  </link>

  <link name="RFT64-6A01">
    <!-- <visual>
      <origin rpy="0 0 0" xyz="0 0 0"/>
      <geometry>
        <mesh filename="meshes/indy12_v2/link7.stl"/>
      </geometry>
      <material name="metal_grey"/>
    </visual> -->

    <inertial>
      <origin rpy="0 0 0" xyz="0.0001815 -0.0001841 0.0154598"/>
      <mass value="0.175"/>
      <inertia ixx="+0.00174119" ixy="0.00000018" ixz="+0.00000083" iyy="+0.00173263" iyz="-0.00000199" izz="+0.00223183"/>
    </inertial>
  </link>

  <link name="tool_changer">
    <!-- <visual>
      <origin rpy="0 0 0" xyz="0 0 0"/>
      <geometry>
        <mesh filename="meshes/indy12_v2/link7.stl"/>
      </geometry>
      <material name="metal_grey"/>
    </visual> -->

    <inertial>
      <origin rpy="0 0 0" xyz="0.0003115 -0.0005641 0.0664598"/>
      <mass value="2.125"/>
      <inertia ixx="+0.00174119" ixy="0.00000018" ixz="+0.00000083" iyy="+0.00173263" iyz="-0.00000199" izz="+0.00223183"/>
    </inertial>
  </link>

  <link name="tcp">
    <inertial>
      <mass value="0.000001" />
      <origin xyz="0.0 0.0 0.0" rpy="0 0 0" />
      <inertia ixx="0.000001" ixy="0" ixz="0" iyy="0.000001" iyz="0" izz="0.000001" />
    </inertial>
  </link>

 <joint name="joint0" type="revolute">
    <parent link="link0"/>
    <child link="link1"/>
    <origin rpy="0 0 0" xyz="+0.00000000 +0.00000000 +0.0820000"/>
    <axis xyz="0 0 1"/>
    <limit effort="10" lower="-3.0543261909900763" upper="3.0543261909900763" velocity="1"/>
  </joint>
  <joint name="joint1" type="revolute">
    <parent link="link1"/>
    <child link="link2"/>
    <origin rpy="0.0 0.0 0" xyz="+0.00000000 -0.13600000 0.26800000"/>
    <axis xyz="0 1 0"/>
    <limit effort="10" lower="-3.0543261909900763" upper="3.0543261909900763" velocity="1"/>
  </joint>
  <joint name="joint2" type="revolute">
    <parent link="link2"/>
    <child link="link3"/>
    <origin rpy="0 0 0" xyz="0 -0.11100000 0.29300000"/>
    <axis xyz="0 0 1"/>
    <limit effort="10" lower="-3.0543261909900763" upper="3.0543261909900763" velocity="1"/>
  </joint>
  <joint name="joint3" type="revolute">
    <parent link="link3"/>
    <child link="link4"/>
    <origin rpy="0 0 0" xyz="0.0 0.12950000 0.35750000"/>
    <axis xyz="0 1 0"/>
    <limit effort="10" lower="-3.0543261909900763" upper="3.0543261909900763" velocity="1"/>
  </joint>
  <joint name="joint4" type="revolute">
    <parent link="link4"/>
    <child link="link5"/>
    <origin rpy="0 0 0" xyz="0 0.10650000 0.20900000"/>
    <axis xyz="0 0 1"/>
    <limit effort="10" lower="-3.0543261909900763" upper="3.0543261909900763" velocity="1"/>
  </joint>
  <joint name="joint5" type="revolute">
    <parent link="link5"/>
    <child link="link6"/>
    <origin rpy="0 0 0" xyz="0 0.12900000 0.36250000"/>
    <axis xyz="0 1 0"/>
    <limit effort="10" lower="-3.0543261909900763" upper="3.0543261909900763" velocity="1"/>
  </joint>
  <joint name="joint6" type="revolute">
    <parent link="link6"/>
    <child link="link7"/>
    <origin rpy="0 0 0" xyz="0 0.07950000 +0.07455"/>
    <axis xyz="0 0 1"/>
    <limit effort="10" lower="-3.0543261909900763" upper="3.0543261909900763" velocity="1"/>
  </joint>
  <joint name="plange_fixed" type="fixed">
    <parent link="link7"/>
    <child link="tool_plange"/>
    <origin rpy="0 0 0" xyz="0 0 0.0900"/>
  </joint>
  <joint name="RFT_fixed" type="fixed">
    <parent link="tool_plange"/>
    <child link="RFT64-6A01"/>
    <origin rpy="0 0 0" xyz="0 0 0.0497"/>
  </joint>
  <joint name="changer_fixed" type="fixed">
    <parent link="RFT64-6A01"/>
    <child link="tool_changer"/>
    <origin rpy="0 0 0" xyz="0 0 0.001"/>
  </joint>
  <joint name="tcp_fixed" type="fixed">
    <parent link="tool_changer"/>
    <child link="tcp"/>
    <origin rpy="0 0 0" xyz="0 0 0.067"/>
  </joint>


  <link name="gripper_body">
      <inertial>
        <origin xyz="-0.0015545, 0.00321883, 0.0655864"  rpy="0 0 0" />        
        <mass value="4.6"/>
        <inertia  ixx="0.0416187"      ixy=" 3.92703e-06"      ixz="1.67884e-05"      iyy="0.0330923"      iyz="0.00525243"      izz=" 0.0269927" />
     </inertial>
    <visual>
        <origin xyz="0 0 0"  rpy="0 0 0" />
        <geometry>
            <mesh filename="meshes/LEE.stl" />
        </geometry>
      <material name="metal_gray">
        <color rgba="0.75294 0.75294 0.75294 1" />
      </material>
    </visual>
    <collision>
       <origin xyz="0 0 0"  rpy="0 0 0" />
        <geometry>
            <mesh filename="meshes/LEE.stl" />
        </geometry>
    </collision>
  </link>

   <!-- <link name="gripper_r">
      <inertial>
        <origin xyz="-0.0193096 0.0710776  0.0252162"  rpy="0 0 0" />
        <mass value="0.219219"/>
        <inertia  ixx="0.000366064"      ixy="-7.07163e-05"      ixz="-7.03228e-05"      iyy="0.000237798"      iyz="-7.31083e-05"      izz="0.000338674" />
     </inertial>
    <visual>
        <origin xyz="0 0 0"  rpy="0 0 0" />
        <geometry>
            <mesh filename="meshes/indy12_v2/gripper.stl" />
        </geometry>
      <material name="metal_gray">
        <color rgba="0.75294 0.75294 0.75294 1" />
      </material>
    </visual>
    <collision>
       <origin xyz="0 0 0"  rpy="0 0 0" />
        <geometry>
            <mesh filename="meshes/indy12_v2/gripper.stl" />
        </geometry>
    </collision>
  </link>
   <link name="gripper_l">
      <inertial>
        <origin xyz="-0.0193096 0.0710776  0.0252162"  rpy="0 0 0" />
        <mass value="0.219219"/>
        <inertia  ixx="0.000366064"      ixy="-7.07163e-05"      ixz="-7.03228e-05"      iyy="0.000237798"      iyz="-7.31083e-05"      izz="0.000338674" />
     </inertial>
    <visual>
        <origin xyz="0 0 0"  rpy="0 0 0" />
        <geometry>
            <mesh filename="meshes/indy12_v2/gripper.stl" />
        </geometry>
      <material name="metal_gray">
        <color rgba="0.75294 0.75294 0.75294 1" />
      </material>
    </visual>
    <collision>
       <origin xyz="0 0 0"  rpy="0 0 0" />
        <geometry>
            <mesh filename="meshes/indy12_v2/gripper.stl" />
        </geometry>
    </collision>
  </link> -->

  <joint name="gripper_fixed" type="fixed">
    <parent link="tcp"/>
    <child link="gripper_body"/>
    <origin xyz="0 0 0.00" rpy="0 0 0"/>
  </joint>
</robot>

