<?xml version="1.0" ?>

<robot name="kr_120_plate_kr_250_rail" xmlns:xacro="http://ros.org/wiki/xacro">
    <material name="metal_grey"> <color rgba="1 1 1 1"/> </material>
  <material name="white_grey"> <color rgba="0.8 0.8 0.8 1"/> </material>
  <material name="black"> <color rgba="0.0 0.0 0.0 1"/> </material>
  <material name="white"> <color rgba="1 1 1 1"/> </material>
    <material name="darkblue"> <color rgba="0 0 0.5 1"/> </material>
        <material name="gold"> <color rgba="  0.82745      0.68627      0.21569 1"/> </material>

  <link name="world"/>

  <link name="r_plate_link">
    <visual>
      <origin rpy="0 0 0" xyz="0 0 0"/>
      <geometry>
        <mesh filename="meshes/right_plate.stl"/>
      </geometry>
      <material name="black"/>
    </visual>
  </link>

  <link name="r_base_link">
    <visual>
      <origin rpy="0 0 0" xyz="0 0 0"/>
      <geometry>
        <mesh filename="meshes/kuka_kr_120_base_link.stl"/>
      </geometry>
      <material name="black"/>
    </visual>

    <inertial>
      <origin rpy="0 0 0" xyz="0 0 0"/>
      <mass value="257.693"/>
      <inertia ixx="5.9791" iyy="13.1238" izz="16.0208" iyz="-0.00780437" ixz="1.37877" ixy="0.0327832"/>
    </inertial>
  </link>
  <link name="r_link1">
    <visual>
      <origin rpy="0 0 0" xyz="0 0 0"/>
      <geometry>
        <mesh filename="meshes/kuka_kr_120_link1.stl"/>
      </geometry>
      <material name="black"/>
    </visual>
 
    <inertial>
      <origin rpy="0 0 0" xyz="0 0 0"/>
      <mass value="254.573"/>
      <inertia ixx="8.21089" iyy="15.5349" izz="13.9837" iyz="-0.23054" ixz=" 0.790915" ixy="1.29514"/>
    </inertial>
  </link>
  <link name="r_link2">
    <visual>
      <origin rpy="0 0 0" xyz="0 0 0"/>
      <geometry>
        <mesh filename="meshes/kuka_kr_120_link2.stl"/>
      </geometry>
      <material name="black"/>
    </visual>
   
    <inertial>
      <origin rpy="0 0 0" xyz="0 0 0"/>
      <mass value="331.528"/>
      <inertia ixx="5.60972" iyy="65.6326" izz="64.9414" iyz="-0.00657388" ixz=" 4.37003" ixy="0.180956"/>
    </inertial>
  </link>
  <link name="r_link3">
    <visual>
      <origin rpy="0 0 0" xyz="0 0 0"/>
      <geometry>
        <mesh filename="meshes/kuka_kr_120_link3.stl"/>
      </geometry>
      <material name="black"/>
    </visual>
    <collision>
      <origin rpy="0 0 0" xyz="0 0 0"/>
      <geometry>
        <mesh filename="meshes/kuka_kr_120_link3.stl"/>
      </geometry>
    </collision>         
   
    <inertial>
      <origin rpy="0 0 0" xyz="0 0 0"/>
      <mass value="172.325"/>
      <inertia ixx="1.66847" iyy="14.9789" izz="14.9091" iyz="0.0995061" ixz="-0.374194" ixy="0.0156184"/>
    </inertial>
  </link>
  <link name="r_link4">
    <visual>
      <origin rpy="0 0 0" xyz="0 0 0"/>
      <geometry>
        <mesh filename="meshes/kuka_kr_120_link4.stl"/>
      </geometry>
      <material name="black"/>
    </visual>
 
   
    <inertial>
      <origin rpy="0 0 0" xyz="0 0 0"/>
      <mass value="18.8575"/>
      <inertia ixx="0.332037" iyy="0.33071" izz="0.0462583" iyz="-8.34095e-06" ixz="0.0151001" ixy="3.83858e-06"/>
    </inertial>
  </link>
  <link name="r_link5">
    <visual>
      <origin rpy="0 0 0" xyz="0 0 0"/>
      <geometry>
        <mesh filename="meshes/kuka_kr_120_link5.stl"/>
      </geometry>
      <material name="black"/>
    </visual>
   
    <inertial>
      <origin rpy="0 0 0" xyz="0 0 0"/>
      <mass value="37.375"/>
      <inertia ixx="0.22791" iyy="0.32026" izz="0.201587" iyz="-0.00012791" ixz="0.0560059" ixy="-7.78827e-05"/>
    </inertial>
  </link>
  <link name="r_link6">
    <visual>
      <origin rpy="0 0 0" xyz="0 0 0"/>
      <geometry>
        <mesh filename="meshes/kuka_kr_120_link6.stl"/>
      </geometry>
      <material name="black"/>
    </visual>
   
    <inertial>
      <origin rpy="0 0 0" xyz="0 0 0"/>
      <mass value="3.13638"/>
      <inertia ixx="0.00284771" iyy="0.00285497" izz="0.00512802" iyz="1.48688e-07" ixz="-9.18771e-07" ixy="3.80765e-08"/>
    </inertial>
  </link>




  <link name="r_FTSensor">
    <visual>
      <geometry>
        <mesh filename="meshes/kuka_120_ft_sensor.stl"/>
      </geometry>
      <origin rpy="0 0 0" xyz="0.00 0 0"/>
    </visual>
    <inertial>
      <mass value="0.001"/>
      <origin rpy="0 0 0" xyz="0.0 0.0 0.0"/>
      <inertia ixx="0.0" ixy="0.0" ixz="0.0" iyy="0.0" iyz="0.0" izz="0.0"/>
    </inertial>
  </link>
  <link name="r_TGT">
    <visual>
      <geometry>
        <mesh filename="meshes/TGT.stl"/>
      </geometry>
      <origin rpy="0 0 0" xyz="0.00 0 0"/>
        <material name="gold_"> <color rgba="1 0.7 0 1"/> </material>
    </visual>

    <inertial>
      <mass value="0.001"/>
      <origin rpy="0 0 0" xyz="0.0 0.0 0.0"/>
      <inertia ixx="0.0" ixy="0.0" ixz="0.0" iyy="0.0" iyz="0.0" izz="0.0"/>
    </inertial>
  </link>
  <link name="r_TGT_pannel">
    <visual>
      <geometry>
        <mesh filename="meshes/TGT_pannel.stl"/>
      </geometry>
      <origin rpy="0 0 0" xyz="0.00 0 0"/>
            <material name="darkblue"/>

    </visual>
    <inertial>
      <mass value="0.001"/>
      <origin rpy="0 0 0" xyz="0.0 0.0 0.0"/>
      <inertia ixx="0.0" ixy="0.0" ixz="0.0" iyy="0.0" iyz="0.0" izz="0.0"/>
    </inertial>
  </link>

  <link name="r_TGT_launcherring">
    <visual>
      <geometry>
        <mesh filename="meshes/TGT_launcherring.stl"/>
      </geometry>
      <origin rpy="0 0 0" xyz="0.00 0 0"/>
            <material name="metal_grey"/>

    </visual>
    <inertial>
      <mass value="0.001"/>
      <origin rpy="0 0 0" xyz="0.0 0.0 0.0"/>
      <inertia ixx="0.0" ixy="0.0" ixz="0.0" iyy="0.0" iyz="0.0" izz="0.0"/>
    </inertial>
  </link>

  <link name="r_TGT_fixture">
    <visual>
      <geometry>
        <mesh filename="meshes/TGT_fixture.stl"/>
      </geometry>
      <origin rpy="0 0 0" xyz="0.00 0 0"/>
            <material name="metal_grey"/>

    </visual>
    <inertial>
      <mass value="0.001"/>
      <origin rpy="0 0 0" xyz="0.0 0.0 0.0"/>
      <inertia ixx="0.0" ixy="0.0" ixz="0.0" iyy="0.0" iyz="0.0" izz="0.0"/>
    </inertial>
  </link>

<!-- robot_joint -->
  <joint name="r_joint1" type="revolute">
    <parent link="r_base_link"/>     
    <child link="r_link1"/>  
    <origin rpy="3.14159265358 0.0 0.0" xyz="0.0 0.0 0.2356"/>
    <axis xyz="0 0 1"/>
    <limit effort="100000" lower="-3.2289" upper="3.2289" velocity="1000"/>
    <!-- <limit effort="100000" lower="-3.05432619099" upper="3.05432619099" velocity="1000"/> -->
  </joint>
  <joint name="r_joint2" type="revolute">
    <parent link="r_link1"/>  
    <child link="r_link2"/>  
    <origin rpy="1.57079632679 0.0 0.0" xyz="0.33 0.0 -0.4094"/>
    <axis xyz="0 0 1"/>
    <limit effort="100000" lower="-2.4435" upper="-0.0873" velocity="1000"/>
    <!-- <limit effort="100000" lower="-3.05432619099" upper="3.05432619099" velocity="1000"/> -->
  </joint>
  <joint name="r_joint3" type="revolute">
    <parent link="r_link2"/> 
    <child link="r_link3"/>    
    <origin rpy="0.0 0.0 0.0" xyz="1.15 0.0 -0.095"/>
    <axis xyz="0 0 1"/>
    <limit effort="100000" lower="-2.0944" upper="2.9322" velocity="1000"/>
    <!-- <limit effort="100000" lower="-3.05432619099" upper="3.05432619099" velocity="1000"/> -->
  </joint>
  <joint name="r_joint4" type="revolute">
    <parent link="r_link3"/>  
    <child link="r_link4"/>   
    <origin rpy="0.0 -1.57079632679 0.0" xyz="0.8785 -0.115 0.095"/>
    <axis xyz="0 0 1"/>
    <limit effort="100000" lower="-6.1087" upper="6.1087" velocity="1000"/>
    <!-- <limit effort="100000" lower="-3.05432619099" upper="3.05432619099" velocity="1000"/> -->
  </joint>
  <joint name="r_joint5" type="revolute">
    <parent link="r_link4"/>  
    <child link="r_link5"/>   
    <origin rpy="0.0 1.57079632679 0.0" xyz="0.059 0.0 -0.3415"/>
    <axis xyz="0 0 1"/>
    <limit effort="100000" lower="-2.1817" upper="2.1817" velocity="1000"/>
  </joint>
  <joint name="r_joint6" type="revolute">
    <parent link="r_link5"/>  
    <child link="r_link6"/>
    <origin rpy="0.0 -1.57079632679 0.0" xyz="0.195 0.0 -0.059"/>
    <axis xyz="0 0 1"/>
    <limit effort="100000" lower="-6.1087" upper="6.1087" velocity="1000"/>
  </joint>

<!-- other link -->
  <link name="r_tcp">
    <inertial>
      <mass value="0"/>
      <origin rpy="0 0 0" xyz="0.0 0.0 0.0"/>
      <inertia ixx="0.0" ixy="0.0" ixz="0.0" iyy="0.0" iyz="0.0" izz="0.0"/>
    </inertial>
  </link>

  <link name="sat_CoM">
  <inertial>
    <origin xyz="0 0 00" rpy="0 0 0" />
    <mass value="00" />
    <inertia ixx="0" ixy="0.0" ixz="0.0" iyy="0.0" iyz="0.0" izz="0.0" />
  </inertial>
  </link>

<!-- other joint -->
  <joint name="r_world_joint" type="fixed">
    <parent link="world"/>
    <child link="r_plate_link"/>
    <origin rpy="0.0 0.0 3.141592" xyz="0 0 0"/>
  </joint>
  <joint name="r_plate_base_joint" type="fixed">
    <parent link="r_plate_link"/>     
    <child link="r_base_link"/>  
    <origin rpy="0.0 0.0 3.14159265358" xyz="0.0 0.0 0.05"/>
  </joint>   
  <joint name="r_tcp_joint" type="fixed">
    <parent link="r_link6"/>
    <child link="r_tcp"/>
    <origin rpy="3.1415926536 0.0 1.5707963268" xyz="0.0 0.0 -0.02"/>
  </joint> 

  <joint name="r_ft_sensor_joint" type="fixed">
    <parent link="r_tcp"/>
    <child link="r_FTSensor"/>
    <origin rpy="0.0 0  3.1415926536" xyz="0.0 0.0 0.08588"/>
  </joint> 
  <joint name="r_TGT_fixed" type="fixed">
    <parent link="r_FTSensor"/>
    <child link="r_TGT"/>
    <origin rpy="0.0 0.0 0.0" xyz="0.0 0.0 0.0"/>
  </joint> 

  <joint name="r_TGT_pannel_fixed" type="fixed">
    <parent link="r_FTSensor"/>
    <child link="r_TGT_pannel"/>
    <origin rpy="0.0 0.0 0.0" xyz="0.0 0.0 0.0"/>
  </joint> 

  <joint name="r_TGT_launchering_fixed" type="fixed">
    <parent link="r_FTSensor"/>
    <child link="r_TGT_launcherring"/>
    <origin rpy="0.0 0.0 0.0" xyz="0.0 0.0 0.0"/>
  </joint> 

  <joint name="r_TGT_fixture_fixed" type="fixed">
    <parent link="r_FTSensor"/>
    <child link="r_TGT_fixture"/>
    <origin rpy="0.0 0.0 0.0" xyz="0.0 0.0 0.0"/>
  </joint> 

  <!-- [ToDo] update CoM Position -->
  <joint name="tcp_CoM_fixed" type="fixed">
    <origin xyz="-0.00001166 -0.00000932 -0.04673098" rpy="0 0 0" />
    <parent link="r_TGT" />
    <child link="sat_CoM" />
    <axis xyz="0 0 0" />
  </joint>

</robot>

