<?xml version="1.0" ?>
<!-- =================================================================================== -->
<!-- |    This document was autogenerated by xacro from mir.urdf.xacro                 | -->
<!-- |    EDITING THIS FILE BY HAND IS NOT RECOMMENDED                                 | -->
<!-- =================================================================================== -->
<robot name="mir250_ppr">
  <!-- Virtual PPR Joints -->
 <link name="world">
      <inertial>
          <mass value="0.000001" />
          <origin xyz="0.0 0.0 0.0" rpy="0 0 0" />
          <inertia ixx="0.000001" ixy="0" ixz="0" iyy="0.000001" iyz="0" izz="0.000001" />
      </inertial>
  </link>
  <joint name="lin_x_joint" type="prismatic">
    <origin rpy="0 0 0" xyz="0 0 0"/>
    <axis xyz="1 0 0"/>
    <limit effort="1000.0" lower="-1e+16" upper="1e+16" velocity="3.5"/>
    <joint_properties damping="1" friction="1"/>
    <parent link="world"/>
    <child link="lin_x_link"/>
  </joint>
  <link name="lin_x_link">
      <inertial>
          <mass value="0.000001" />
          <origin xyz="0.0 0.0 0.0" rpy="0 0 0" />
          <inertia ixx="0.000001" ixy="0" ixz="0" iyy="0.000001" iyz="0" izz="0.000001" />
      </inertial>
  </link>
  <joint name="lin_y_joint" type="prismatic">
    <origin rpy="0 0 0" xyz="0 0 0"/>
    <axis xyz="0 1 0"/>
    <limit effort="1000.0" lower="-1e+16" upper="1e+16" velocity="3.5"/>
    <joint_properties damping="1" friction="1"/>
    <parent link="lin_x_link"/>
    <child link="lin_y_link"/>
  </joint>
  <link name="lin_y_link">
      <inertial>
          <mass value="0.000001" />
          <origin xyz="0.0 0.0 0.0" rpy="0 0 0" />
          <inertia ixx="0.000001" ixy="0" ixz="0" iyy="0.000001" iyz="0" izz="0.000001" />
      </inertial>
  </link>
  <joint name="rot_z_joint" type="revolute">
    <origin rpy="0 0 0" xyz="0 0 0"/>
    <axis xyz="0 0 1"/>
    <limit effort="1000.0" lower="-1e+16" upper="1e+16" velocity="3.5"/>
    <joint_properties damping="1" friction="1"/>
    <parent link="lin_y_link"/>
    <child link="base_link"/>
  </joint>

<link name="base_link">
    <inertial>
      <mass value="97.0"/>
      <origin rpy="0 0 0" xyz="-0.054485000000000006 0.0 0.15"/>
      <inertia ixx="1.050832913" ixy="0.0" ixz="0.0" iyy="2.344165729" iyz="0.0" izz="2.7483322339999994"/>
    </inertial>
    <visual>
      <origin rpy="1.5709 0 0" xyz="0.0 0 0"/>
      <geometry>
        <mesh filename="meshes/untitled.obj" scale = "0.05 0.05 0.05"/>
      </geometry>
      <material name="white">
        <color rgba="1 1 1 1"/>
      </material>
    </visual>
  </link>
  <!-- IMU -->
  <joint name="base_link_to_imu_joint" type="fixed">
    <parent link="base_link"/>
    <child link="imu_link"/>
    <origin rpy="0 0 0" xyz="0.0 0.0 0.25"/>
    <!-- same as real MiR -->
  </joint>
  <link name="imu_link">
        <inertial>
          <mass value="0.000001" />
          <origin xyz="0.0 0.0 0.0" rpy="0 0 0" />
          <inertia ixx="0.000001" ixy="0" ixz="0" iyy="0.000001" iyz="0" izz="0.000001" />
      </inertial>
  </link>
  <!-- Create an alias for imu_link. This is necessary because the real MiR's
         TF has imu_link, but the imu_data topic is published in the imu_frame
         frame. -->
  <joint name="imu_link_to_imu_frame_joint" type="fixed">
    <parent link="imu_link"/>
    <child link="imu_frame"/>
    <origin rpy="0 0 0" xyz="0 0 0"/>
  </joint>
  <link name="imu_frame">
        <inertial>
          <mass value="0.000001" />
          <origin xyz="0.0 0.0 0.0" rpy="0 0 0" />
          <inertia ixx="0.000001" ixy="0" ixz="0" iyy="0.000001" iyz="0" izz="0.000001" />
      </inertial>
  </link>
  <!-- Laser scanners -->
  <joint name="base_link_to_front_laser_joint" type="fixed">
    <parent link="base_link"/>
    <child link="front_laser_link"/>
    <origin rpy="0.0 0.0 0.7853981633974483" xyz="0.310515 0.205 0.1914"/>
  </joint>
  <link name="front_laser_link">    
    <inertial>
      <mass value="1.2"/>
      <origin xyz="0 0 0"/>
      <inertia ixx="0.005824997669999999" ixy="0.0" ixz="0.0" iyy="0.00585609765756" iyz="0.0" izz="0.00483609806556"/>
    </inertial>
  </link>

  <joint name="base_link_to_back_laser_joint" type="fixed">
    <parent link="base_link"/>
    <child link="back_laser_link"/>
    <origin rpy="0.0 0.0 -2.356194490192345" xyz="-0.319485 -0.205 0.1914"/>
  </joint>
  <link name="back_laser_link">
    <inertial>
      <mass value="1.2"/>
      <origin xyz="0 0 0"/>
      <inertia ixx="0.005824997669999999" ixy="0.0" ixz="0.0" iyy="0.00585609765756" iyz="0.0" izz="0.00483609806556"/>
    </inertial>
  </link>

  <!-- Ultrasound sensors -->
  <joint name="us_1_joint" type="fixed">
    <!-- right ultrasound -->
    <parent link="base_link"/>
    <child link="us_1_frame"/>
    <origin rpy="0 0 0" xyz="0.45 -0.12 0.16 "/>
    <!-- from visually matching to the mesh of the MiR -->
  </joint>
  <link name="us_1_frame">
        <inertial>
          <mass value="0.000001" />
          <origin xyz="0.0 0.0 0.0" rpy="0 0 0" />
          <inertia ixx="0.000001" ixy="0" ixz="0" iyy="0.000001" iyz="0" izz="0.000001" />
      </inertial>
  </link>
  <joint name="us_2_joint" type="fixed">
    <!-- left ultrasound -->
    <parent link="base_link"/>
    <child link="us_2_frame"/>
    <origin rpy="0 0 0" xyz="0.45 0.12 0.16 "/>
    <!-- from visually matching to the mesh of the MiR -->
  </joint>
  <link name="us_2_frame">
        <inertial>
          <mass value="0.000001" />
          <origin xyz="0.0 0.0 0.0" rpy="0 0 0" />
          <inertia ixx="0.000001" ixy="0" ixz="0" iyy="0.000001" iyz="0" izz="0.000001" />
      </inertial>
  </link>
  <joint name="left_wheel_joint" type="fixed">
    <origin rpy="0 0 0" xyz="0.0 0.2015 0.1"/>
    <parent link="base_link"/>
    <child link="left_wheel_link"/>
    <axis xyz="0 1 0"/>
    <limit effort="100" velocity="20.0"/>
  </joint>
  <link name="left_wheel_link">
    <inertial>
      <mass value="1.0"/>
      <origin rpy="1.5707963267948966 0 0" xyz="0 0 0"/>
      <inertia ixx="0.0026203322852000007" ixy="0.0" ixz="0.0" iyy="0.0026203322852000007" iyz="0.0" izz="0.005000000000000001"/>
    </inertial>

  </link>
  <joint name="right_wheel_joint" type="fixed">
    <origin rpy="0 0 0" xyz="0.0 -0.2015 0.1"/>
    <parent link="base_link"/>
    <child link="right_wheel_link"/>
    <axis xyz="0 1 0"/>
    <limit effort="100" velocity="20.0"/>
  </joint>
  <link name="right_wheel_link">
    <inertial>
      <mass value="1.0"/>
      <origin rpy="1.5707963267948966 0 0" xyz="0 0 0"/>
      <inertia ixx="0.0026203322852000007" ixy="0.0" ixz="0.0" iyy="0.0026203322852000007" iyz="0.0" izz="0.005000000000000001"/>
    </inertial>

  </link>
  <!-- caster hub -->
  <joint name="fl_caster_rotation_joint" type="fixed">
    <origin rpy="0 0 0" xyz="0.299215 0.188 0.1565"/>
    <parent link="base_link"/>
    <child link="fl_caster_rotation_link"/>
    <axis xyz="0 0 1"/>
    <dynamics damping="0.01" friction="0.0"/>
  </joint>
  <link name="fl_caster_rotation_link">
    <inertial>
      <!-- <origin xyz="0 0 -0.042500000044" rpy="${0.5 * pi} ${24 * deg_to_rad} ${1.5 * pi}" /> -->
      <origin rpy="0.41887903200000004 0 1.5707963267948966 " xyz="0 0 -0.042500000044"/>
      <mass value="0.3097539019"/>
      <inertia ixx="0.0005844517978" ixy="0" ixz="0" iyy="0.00052872551237" iyz="0" izz="0.00017923555074"/>
    </inertial>


  </link>
  <!-- caster wheel -->
  <joint name="fl_caster_wheel_joint" type="fixed">
    <origin rpy="0 0 0" xyz="-0.0382 0 -0.094"/>
    <parent link="fl_caster_rotation_link"/>
    <child link="fl_caster_wheel_link"/>
    <axis xyz="0 1 0"/>
  </joint>
  <link name="fl_caster_wheel_link">
    <inertial>
      <mass value="1.0"/>
      <origin rpy="1.5707963267948966 0 0" xyz="0 0 0"/>
      <inertia ixx="0.001061895408575" ixy="0.0" ixz="0.0" iyy="0.001061895408575" iyz="0.0" izz="0.001953125"/>
    </inertial>

  </link>
  <!-- caster hub -->
  <joint name="fr_caster_rotation_joint" type="fixed">
    <origin rpy="0 0 0" xyz="0.299215 -0.188 0.1565"/>
    <parent link="base_link"/>
    <child link="fr_caster_rotation_link"/>
    <axis xyz="0 0 1"/>
    <dynamics damping="0.01" friction="0.0"/>
  </joint>
  <link name="fr_caster_rotation_link">
    <inertial>
      <!-- <origin xyz="0 0 -0.042500000044" rpy="${0.5 * pi} ${24 * deg_to_rad} ${1.5 * pi}" /> -->
      <origin rpy="0.41887903200000004 0 1.5707963267948966 " xyz="0 0 -0.042500000044"/>
      <mass value="0.3097539019"/>
      <inertia ixx="0.0005844517978" ixy="0" ixz="0" iyy="0.00052872551237" iyz="0" izz="0.00017923555074"/>
    </inertial>

  </link>
  <!-- caster wheel -->
  <joint name="fr_caster_wheel_joint" type="fixed">
    <origin rpy="0 0 0" xyz="-0.0382 0 -0.094"/>
    <parent link="fr_caster_rotation_link"/>
    <child link="fr_caster_wheel_link"/>
    <axis xyz="0 1 0"/>
  </joint>
  <link name="fr_caster_wheel_link">
    <inertial>
      <mass value="1.0"/>
      <origin rpy="1.5707963267948966 0 0" xyz="0 0 0"/>
      <inertia ixx="0.001061895408575" ixy="0.0" ixz="0.0" iyy="0.001061895408575" iyz="0.0" izz="0.001953125"/>
    </inertial>

  </link>
  <!-- caster hub -->
  <joint name="bl_caster_rotation_joint" type="fixed">
    <origin rpy="0 0 0" xyz="-0.300485 0.188 0.1565"/>
    <parent link="base_link"/>
    <child link="bl_caster_rotation_link"/>
    <axis xyz="0 0 1"/>
    <dynamics damping="0.01" friction="0.0"/>
  </joint>
  <link name="bl_caster_rotation_link">
    <inertial>
      <!-- <origin xyz="0 0 -0.042500000044" rpy="${0.5 * pi} ${24 * deg_to_rad} ${1.5 * pi}" /> -->
      <origin rpy="0.41887903200000004 0 1.5707963267948966 " xyz="0 0 -0.042500000044"/>
      <mass value="0.3097539019"/>
      <inertia ixx="0.0005844517978" ixy="0" ixz="0" iyy="0.00052872551237" iyz="0" izz="0.00017923555074"/>
    </inertial>
  </link>
  <!-- caster wheel -->
  <joint name="bl_caster_wheel_joint" type="fixed">
    <origin rpy="0 0 0" xyz="-0.0382 0 -0.094"/>
    <parent link="bl_caster_rotation_link"/>
    <child link="bl_caster_wheel_link"/>
    <axis xyz="0 1 0"/>
  </joint>
  <link name="bl_caster_wheel_link">
    <inertial>
      <mass value="1.0"/>
      <origin rpy="1.5707963267948966 0 0" xyz="0 0 0"/>
      <inertia ixx="0.001061895408575" ixy="0.0" ixz="0.0" iyy="0.001061895408575" iyz="0.0" izz="0.001953125"/>
    </inertial>
  </link>
  <!-- caster hub -->
  <joint name="br_caster_rotation_joint" type="fixed">
    <origin rpy="0 0 0" xyz="-0.300485 -0.188 0.1565"/>
    <parent link="base_link"/>
    <child link="br_caster_rotation_link"/>
    <axis xyz="0 0 1"/>
    <dynamics damping="0.01" friction="0.0"/>
  </joint>
  <link name="br_caster_rotation_link">
    <inertial>
      <!-- <origin xyz="0 0 -0.042500000044" rpy="${0.5 * pi} ${24 * deg_to_rad} ${1.5 * pi}" /> -->
      <origin rpy="0.41887903200000004 0 1.5707963267948966 " xyz="0 0 -0.042500000044"/>
      <mass value="0.3097539019"/>
      <inertia ixx="0.0005844517978" ixy="0" ixz="0" iyy="0.00052872551237" iyz="0" izz="0.00017923555074"/>
    </inertial>

  </link>
  <!-- caster wheel -->
  <joint name="br_caster_wheel_joint" type="fixed">
    <origin rpy="0 0 0" xyz="-0.0382 0 -0.094"/>
    <parent link="br_caster_rotation_link"/>
    <child link="br_caster_wheel_link"/>
    <axis xyz="0 1 0"/>
  </joint>
  <link name="br_caster_wheel_link">
    <inertial>
      <mass value="1.0"/>
      <origin rpy="1.5707963267948966 0 0" xyz="0 0 0"/>
      <inertia ixx="0.001061895408575" ixy="0.0" ixz="0.0" iyy="0.001061895408575" iyz="0.0" izz="0.001953125"/>
    </inertial>

  </link>
    
  <joint name="endeffector" type="fixed">
    <origin rpy="0.0 0.0 0.0" xyz="0.0 0.0 0.0"/>
    <parent link="base_link"/>
    <child link="tool0"/>
  </joint>
  <link name="tool0">
      <inertial>
          <mass value="0.000001" />
          <origin xyz="0.0 0.0 0.0" rpy="0 0 0" />
          <inertia ixx="0.000001" ixy="0" ixz="0" iyy="0.000001" iyz="0" izz="0.000001" />
      </inertial>
  </link>
  
</robot>

