<?xml version="1.0" ?>

<robot name="xarm6">

  <material name="Black">
      <color rgba="0.0 0.0 0.0 1.0"/>
    </material>

    <material name="Red">
      <color rgba="0.8 0.0 0.0 1.0"/>
    </material>

    <material name="White">
      <color rgba="1.0 1.0 1.0 1.0"/>
    </material>

    <material name="Silver">
      <color rgba="0.753 0.753 0.753 1.0"/>
    </material>
    
    <material name="dr_gray">
      <color rgba="0.490 0.490 0.486 1.0"/>
    </material>
    <material name="dr_white">
      <color rgba="0.941 0.941 0.941 1.0"/>
    </material>

    <link name="base">
          <inertial>
            <mass value="0.000001" />
            <origin xyz="0.0 0.0 0.0" rpy="0 0 0" />
            <inertia ixx="0.000001" ixy="0" ixz="0" iyy="0.000001" iyz="0" izz="0.000001" />
        </inertial>
    </link>

    <joint name="base_fixed" type="fixed">
      <parent link="base"/>
      <child link="link_base"/>
    </joint>
  
    <link name="link_base">
      <visual>
        <geometry>
          <mesh filename="package://xarm_description/meshes/xarm6/visual/base.stl"/>
        </geometry>
        <origin xyz="0 0 0" rpy="0 0 0"/>
        <material name="dr_white" />
      </visual>
      <inertial>
      <origin xyz="0.0 0.0 0.09103" rpy="0 0 0" />
      <mass value="2.7" />
      <inertia
        ixx="0.00494875"
        ixy="-3.5E-06"
        ixz="1.25E-05"
        iyy="0.00494174"
        iyz="1.67E-06"
        izz="0.002219" />
      </inertial>
    </link>
    
    <joint name="joint1" type="revolute">
      <parent link="link_base"/>
      <child  link="link1"/>
      <origin xyz="0 0 0.267" rpy="0 0 0"/>
      <axis   xyz="0 0 1"/>
      <limit
        lower="-6.283184"
        upper="6.283184"
        effort="50.0"
        velocity="3.14"/>
      <dynamics damping="1.0" friction="1.0"/>
    </joint>
    
    <link name="link1">
      <visual>
        <geometry>
          <mesh filename="package://xarm_description/meshes/xarm6/visual/link1.stl"/>
        </geometry>
        <origin xyz="0 0 0" rpy="0 0 0"/>
        <material name="dr_white" />
      </visual>
      <inertial>
        <origin xyz="0.013 0.0294 -0.0124" rpy="0 0 0"/>
        <mass value="2.382"/>
        <inertia
          ixx="0.00539427"
          ixy="1.095E-05"
          ixz="1.635E-06"
          iyy="0.0048979"
          iyz="0.000793"
          izz="0.00311573"/>
      </inertial>
    </link>

    <joint name="joint2" type="revolute">
      <parent link="link1"/>
      <child link="link2"/>
      <origin xyz="0 0 0" rpy="0 0 0" />
      <axis xyz="0 1 0"/>
      <limit
        lower="-2.059"
        upper="2.0944"
        effort="50.0"
        velocity="3.14"/>
      <dynamics damping="1.0" friction="1.0"/>
    </joint>
    
    <link name="link2">
      <visual>
        <geometry>
          <mesh filename="package://xarm_description/meshes/xarm6/visual/link2.stl"/>
        </geometry>
        <origin xyz="0 0 0" rpy="-1.5709 0 0"/>
        <material name="dr_white" />
      </visual>
      <inertial>
      <origin
        xyz="0.0388 0.03496 0.2278"
        rpy="0 0 0" />
      <mass
        value="2.267" />
      <inertia
        ixx="0.0248674"
        ixy="-0.00067797"
        ixz="0.00430651"
        iyy="0.02387827,"
        iyz="-0.00457245"
        izz="0.00485548" />
    </inertial>
    </link>

    <joint name="joint3" type="revolute">
      <parent link="link2"/>
      <child link="link3"/>
      <origin xyz="0.0535 0 0.2845" rpy="0 0 0"/>
      <axis xyz="0 1 0"/>
      <limit
        lower="-3.927"
        upper="0.19198"
        effort="32.0"
        velocity="3.14"/>
      <dynamics damping="1.0" friction="1.0"/>
    </joint>
    
    <link name="link3">
      <visual>
        <geometry>
          <mesh filename="package://xarm_description/meshes/xarm6/visual/link3.stl"/>
        </geometry>
        <origin xyz="0 0 0" rpy="-1.5709 0 0"/>
        <material name="dr_white" />
      </visual>
      <inertial>
      <origin
        xyz="0.0704 0.0107 -0.1163"
        rpy="0 0 0" />
      <mass
        value="1.875" />
      <inertia
        ixx="0.0053694"
        ixy="-0.00092094"
        ixz="-0.0014185"
        iyy="0.00501731"
        iyz="0.00169178"
        izz="0.0032423" />
    </inertial>
    </link>

    <joint name="joint4" type="revolute">
      <parent link="link3"/>
      <child link="link4"/>
      <origin xyz="0.0775 0 -0.3425" rpy="0 0 0"/>
      <axis xyz="0 0 -1"/>
      <limit
        lower="-6.283184"
        upper="6.283184"
        effort="32.0"
        velocity="3.14"/>
      <dynamics damping="1.0" friction="1.0"/>
    </joint>
    
    <link name="link4">
      <visual>
        <geometry>
          <mesh filename="package://xarm_description/meshes/xarm6/visual/link4.stl"/>
        </geometry>
        <origin xyz="0 0 0" rpy="-3.141592 0 0"/>
        <material name="dr_white" />
      </visual>
      <inertial>
        <origin xyz="-0.0002 -0.018 0.0229" rpy="0 0 0"/>
        <mass value="1.319"/>
        <inertia
          ixx="4.39263e-03"
          ixy="-5.02800e-05"
          ixz="-1.37400e-05"
          iyy="4.00770e-03,"
          iyz="4.53380e-04"
          izz="1.10321e-03"/>
      </inertial>
    </link>

    <joint name="joint5" type="revolute">
      <parent link="link4"/>
      <child link="link5"/>
      <origin xyz="0 0 0" rpy="0 0 0"/>
      <axis xyz="0 1 0"/>
      <limit
        lower="-1.69297"
        upper="3.141592"
        effort="32.0"
        velocity="3.14"/>
      <dynamics damping="1.0" friction="1.0"/>
    </joint>
    
    <link name="link5">
      <visual>
        <geometry>
          <mesh filename="package://xarm_description/meshes/xarm6/visual/link5.stl"/>
        </geometry>
        <origin xyz="0 0 0" rpy="-1.5709 0 0"/>
        <material name="dr_white" />
      </visual>
      <inertial>
      <origin
        xyz="0.0651 0.00315 -0.03096"
        rpy="0 0 0" />
      <mass
        value="1.34" />
      <inertia
        ixx="0.001202758"
        ixy="-0.00039147"
        ixz="-0.00049243"
        iyy="0.0022876"
        iyz="1.235E-04"
        izz="0.0026866" />
    </inertial>
    </link>

    <joint name="joint6" type="revolute">
      <parent link="link5"/>
      <child link="link6"/>
      <origin xyz="0.076 0 -0.097" rpy="0 0 0"/>
      <axis xyz="0 0 -1"/>
      <limit
        lower="-6.283184"
        upper="6.283184"
        effort="20.0"
        velocity="3.14"/>
      <dynamics damping="1.0" friction="1.0"/>
    </joint>
    
    <link name="link6">
      <visual>
        <geometry>
          <mesh filename="package://xarm_description/meshes/xarm6/visual/link6.stl"/>
        </geometry>
        <origin xyz="0 0 0" rpy="-3.141592 0 0"/>
        <material name="dr_gray" />
      </visual>
      <inertial>
      <origin
        xyz="0 0.00677 0.01098"
        rpy="0 0 0" />
      <mass
        value="0.21" />
      <inertia
        ixx="4.5293E-05"
        ixy="0"
        ixz="0"
        iyy="4.8111E-05"
        iyz="0"
        izz="7.9715E-05" />
    </inertial>
    </link>
    
    <joint name="xarm6_flange_tool0" type="fixed">
    <!-- default toolframe: X+ left, Y+ up, Z+ front -->
      <origin rpy="3.141592 0 0" xyz="0 0 -0.0045"/>
      <parent link="link6"/>
      <child link="xarm6_tool0"/>
    </joint>
  
    <link name="xarm6_tool0">
      <inertial>
          <mass value="0.000001" />
          <origin xyz="0.0 0.0 0.0" rpy="0 0 0" />
          <inertia ixx="0.000001" ixy="0" ixz="0" iyy="0.000001" iyz="0" izz="0.000001" />
      </inertial>
  </link>
  
</robot>
