<?xml version="1.0" ?>

<robot name="kuka_kr_250_rail" xmlns:xacro="http://ros.org/wiki/xacro">
    <material name="metagrey"> <color rgba="1 1 1 1"/> </material>
  <material name="white_grey"> <color rgba="0.8 0.8 0.8 1"/> </material>
  <material name="black"> <color rgba="0.0 0.0 0.0 1"/> </material>
  <material name="white"> <color rgba="1 1 1 1"/> </material>
  <material name="darkblue"> <color rgba="0 0 0.5 1"/> </material>
  <material name="gold"> <color rgba="  0.82745      0.68627      0.21569 1"/> </material>
  <material name="green"> <color rgba="0.0 0.8 0.0 1.0"/> </material>

  <link name="world"/>

<!-- robot_link -->
  <link name="railink">
    <visual>
      <origin rpy="0 0 0" xyz="0 0 0"/>
      <geometry>
        <mesh filename="meshes/kr250/rail_rail.stl"/>
      </geometry>
      <material name="green"/>
    </visual>
   
  </link>
  <link name="raibase_link">
    <visual>
      <origin rpy="0 0 0" xyz="0 0 0"/>
      <geometry>
        <mesh filename="meshes/kr250/rail_base.stl"/>
      </geometry>
      <material name="green"/>
    </visual>
  
  </link>
  <link name="base_link">
    <visual>
      <origin rpy="0 0 0" xyz="0 0 0"/>
      <geometry>
        <mesh filename="meshes/kr250/kuka_kr_250_base_link.stl"/>
      </geometry>
      <material name="green"/>
    </visual>
   
    <inertial>
      <origin rpy="0 0 0" xyz="0 0 0"/>
      <mass value="257.693"/>
      <inertia ixx="5.9791" iyy="13.1238" izz="16.0208" iyz="-0.00780437" ixz="1.37877" ixy="0.0327832"/>
    </inertial>
  </link>
  <link name="link1">
    <visual>
      <origin rpy="0 0 0" xyz="0 0 0"/>
      <geometry>
        <mesh filename="meshes/kr250/kuka_kr_250_link1.stl"/>
      </geometry>
      <material name="green"/>
    </visual>
   
    <inertial>
      <origin rpy="0 0 0" xyz="0 0 0"/>
      <mass value="254.573"/>
      <inertia ixx="8.21089" iyy="15.5349" izz="13.9837" iyz="-0.23054" ixz=" 0.790915" ixy="1.29514"/>
    </inertial>
  </link>
  <link name="link2">
    <visual>
      <origin rpy="0 0 0" xyz="0 0 0"/>
      <geometry>
        <mesh filename="meshes/kr250/kuka_kr_250_link2.stl"/>
      </geometry>
      <material name="green"/>
    </visual>
   
    <inertial>
      <origin rpy="0 0 0" xyz="0 0 0"/>
      <mass value="331.528"/>
      <inertia ixx="5.60972" iyy="65.6326" izz="64.9414" iyz="-0.00657388" ixz=" 4.37003" ixy="0.180956"/>
    </inertial>
  </link>
  <link name="link3">
    <visual>
      <origin rpy="0 0 0" xyz="0 0 0"/>
      <geometry>
        <mesh filename="meshes/kr250/kuka_kr_250_link3.stl"/>
      </geometry>
      <material name="green"/>
    </visual>
   
    <inertial>
      <origin rpy="0 0 0" xyz="0 0 0"/>
      <mass value="172.325"/>
      <inertia ixx="1.66847" iyy="14.9789" izz="14.9091" iyz="0.0995061" ixz="-0.374194" ixy="0.0156184"/>
    </inertial>
  </link>
  <link name="link4">
    <visual>
      <origin rpy="0 0 0" xyz="0 0 0"/>
      <geometry>
        <mesh filename="meshes/kr250/kuka_kr_250_link4.stl"/>
      </geometry>
      <material name="green"/>
    </visual>
  
    <inertial>
      <origin rpy="0 0 0" xyz="0 0 0"/>
      <mass value="18.8575"/>
      <inertia ixx="0.332037" iyy="0.33071" izz="0.0462583" iyz="-8.34095e-06" ixz="0.0151001" ixy="3.83858e-06"/>
    </inertial>
  </link>
  <link name="link5">
    <visual>
      <origin rpy="0 0 0" xyz="0 0 0"/>
      <geometry>
        <mesh filename="meshes/kr250/kuka_kr_250_link5.stl"/>
      </geometry>
      <material name="green"/>
    </visual>

    <inertial>
      <origin rpy="0 0 0" xyz="0 0 0"/>
      <mass value="25.5148"/>
      <inertia ixx="0.367292" iyy="0.533284" izz="0.378389" iyz="-4.25692e-05" ixz="0.10984" ixy="-0.000112698"/>
    </inertial>
  </link>
  <link name="link6">
    <visual>
      <origin rpy="0 0 0" xyz="0 0 0"/>
      <geometry>
        <mesh filename="meshes/kr250/kuka_kr_250_link6.stl"/>
      </geometry>
      <material name="green"/>
    </visual>
   
    <inertial>
      <origin rpy="0 0 0" xyz="0 0 0"/>
      <mass value="2.15518"/>
      <inertia ixx="0.00809075" iyy="0.00810687" izz="0.0156025" iyz="2.33201e-07" ixz="2.37544e-07" ixy="2.74403e-07"/>
    </inertial>
  </link>
<!-- robot_joint -->

  <joint name="jointE" type="prismatic">
    <parent link="railink"/>     
    <child link="raibase_link"/>  
    <!--     <origin rpy="0.0 0.0 0.0" xyz="0.0 0.0 0.363"/> -> 실제 높이 -->
    <origin rpy="0.0 0.0 0.0" xyz="0.665 0.0 0.38"/>
    <axis xyz="1 0 0"/>
    <limit effort="100000" lower="0" upper="3.2289" velocity="1000"/>
  </joint>
  <joint name="joint1" type="revolute">
    <parent link="base_link"/>     
    <child link="link1"/>  
    <origin rpy="3.14159265358 0.0 0.0" xyz="0.0 0.0 0.2356"/>
    <axis xyz="0 0 1"/>
    <limit effort="100000" lower="-3.2289" upper="3.2289" velocity="1000"/>
    <!-- <limit effort="100000" lower="-3.05432619099" upper="3.05432619099" velocity="1000"/> -->
  </joint>
  <joint name="joint2" type="revolute">
    <parent link="link1"/>  
    <child link="link2"/>  
    <origin rpy="1.57079632679 0.0 0.0" xyz="0.33 0.0 -0.4094"/>
    <axis xyz="0 0 1"/>
    <limit effort="100000" lower="-2.4435" upper="-0.0873" velocity="1000"/>
    <!-- <limit effort="100000" lower="-3.05432619099" upper="3.05432619099" velocity="1000"/> -->
  </joint>
  <joint name="joint3" type="revolute">
    <parent link="link2"/> 
    <child link="link3"/>    
    <origin rpy="0.0 0.0 0.0" xyz="1.15 0.0 -0.095"/>
    <axis xyz="0 0 1"/>
    <limit effort="100000" lower="-2.0944" upper="2.9322" velocity="1000"/>
    <!-- <limit effort="100000" lower="-3.05432619099" upper="3.05432619099" velocity="1000"/> -->
  </joint>
  <joint name="joint4" type="revolute">
    <parent link="link3"/>  
    <child link="link4"/>   
    <origin rpy="0.0 -1.57079632679 0.0" xyz="0.8785 -0.115 0.095"/>
    <axis xyz="0 0 1"/>
    <limit effort="100000" lower="-6.1087" upper="6.1087" velocity="1000"/>
    <!-- <limit effort="100000" lower="-3.05432619099" upper="3.05432619099" velocity="1000"/> -->
  </joint>
  
  <joint name="joint5" type="revolute">
    <parent link="link4"/>  
    <child link="link5"/>   
    <origin rpy="0.0 1.57079632679 0.0" xyz="0.059 0.0 -0.3415"/>
    <axis xyz="0 0 1"/>
    <limit effort="100000" lower="-2.1380" upper="2.1380" velocity="1000"/>
    <!-- <limit effort="100000" lower="-3.05432619099" upper="3.05432619099" velocity="1000"/> -->
  </joint>
  
  <joint name="joint6" type="revolute">
    <parent link="link5"/>  
    <child link="link6"/>    
    <origin rpy="0.0 -1.57079632679 0.0" xyz="0.21 0.0 -0.059"/>
    <axis xyz="0 0 1"/>
    <limit effort="100000" lower="-6.1087" upper="6.1087" velocity="1000"/>
    <!-- <limit effort="100000" lower="-3.05432619099" upper="3.05432619099" velocity="1000"/> -->

  </joint>

  <link name="tcp">
    <!-- <collision>
      <geometry>
        <box size="0.01 0.01 0.01"/>
      </geometry>
      <origin rpy="0 0 0" xyz="-0.01 0 0"/>
    </collision> -->
    <inertial>
      <mass value="0"/>
      <origin rpy="0 0 0" xyz="0.0 0.0 0.0"/>
      <inertia ixx="0.0" ixy="0.0" ixz="0.0" iyy="0.0" iyz="0.0" izz="0.0"/>
    </inertial>
  </link>

  <link name="FTSensor">
    <visual>
      <geometry>
        <mesh filename="meshes/ft_sensor.stl"/>
      </geometry>
      <origin rpy="0 0 0" xyz="0.00 0 0"/>
      <material name="green"/>
    </visual>
    <inertial>
      <mass value="0.001"/>
      <origin rpy="0 0 0" xyz="0.0 0.0 0.0"/>
      <inertia ixx="0.0" ixy="0.0" ixz="0.0" iyy="0.0" iyz="0.0" izz="0.0"/>
    </inertial>
  </link>


  <joint name="raibase_joint" type="fixed">
    <parent link="raibase_link"/>     
    <child link="base_link"/>  
    <origin rpy="0.0 0.0 -1.57079632679" xyz="-0.2 0.0 0.0"/>
  </joint> 
  <joint name="tcp_joint" type="fixed">
    <parent link="link6"/>
    <child link="tcp"/>
    <origin rpy="3.1415926536 0.0 1.5707963268" xyz="0.0 0.0 -0.03"/>
  </joint> 
  <joint name="ft_sensor_joint" type="fixed">
    <parent link="tcp"/>
    <child link="FTSensor"/>
    <origin rpy="0.0 0  3.1415926536" xyz="0.0 0.0 0.1048"/>
  </joint> 

  <joint name="world_joint" type="fixed">
    <parent link="world"/>
    <child link="railink"/>
    <origin rpy="0.0 0.0 3.141592" xyz="7.2 0 0"/>
  </joint>
</robot>

